Workbook

Sheet Léeme
B1: Mundial 2026 — Fuente de datos
B2: Corte de resultados | C2: Cargados 54 resultados de fase de grupos (marcador exacto): fechas 1 y 2 completas de los 12 grupos + parte de la fecha 3. El resto se simula. Variables curadas agregadas: puntaje de DT, clasificatorias ponderadas por confederacion y % de jugadores en top-5 ligas (estimaciones ~early-2026). Fuente resultados: Yahoo Sports / Wikipedia por grupo.
B3: Qué es | C3: Planilla de datos estadísticos del Mundial 2026 (USA/México/Canadá, 48 selecciones). Pensada como fuente para que vos hagas tu propio análisis. NO contiene predicciones, modelos, ratings ni probabilidades: solo datos y agregaciones descriptivas de los resultados que cargues.
B4: Hojas
B5: Selecciones | C5: Las 48 selecciones con grupo, confederación, ranking y puntos FIFA, sede, debutante y títulos.
B6: Clasificatorias | C6: Plantilla para cargar el rendimiento de cada selección en sus eliminatorias (PJ, PG, PE, PP, GF, GC). Las columnas derivadas (Pts, DG, %Pts, GF/PJ) se calculan solas.
B7: Predictores_país | C7: Plantilla para cargar variables de país/plantel que pueden servir como predictores (población, PIB, PIB per cápita, valor de plantel, etc.). Con fuentes sugeridas.
B8: Fixture_Grupos | C8: Los 72 partidos de la fase de grupos. Cargás Goles_A y Goles_B; el resto se completa solo.
B9: Posiciones | C9: Tabla de cada grupo. Se calcula automáticamente a partir de lo que cargás en Fixture_Grupos.
B10: Eliminatorias | C10: Plantilla del cuadro final (32avos → final) para cargar a mano a medida que se define.
B11: Código de colores
B12: Azul | C12: Celdas de entrada: las completás vos (resultados, datos de país).
B13: Amarillo | C13: Datos a completar / verificar (p. ej. puntos FIFA de 11 selecciones que no pude cerrar).
B14: Verde | C14: Valores traídos por fórmula desde otra hoja.
B15: Negro | C15: Cálculos / fórmulas.
B16: Sin inferencia | C16: Las 'Posiciones' son una agregación contable de los resultados cargados, no una predicción. El orden dentro del grupo usa (Pts, DG, GF); el desempate oficial de FIFA usa primero el head-to-head, así que tomalo como ordenamiento provisional.
B17: Fuentes
B18: Grupos y formato | C18: Wikipedia — 2026 FIFA World Cup draw / 2026 FIFA World Cup (consultado 24-jun-2026).
B19: Ranking FIFA | C19: Foto del 19-nov-2025 (la usada para el sorteo). Fuente: football-ranking.com (replica el ranking FIFA/Coca-Cola). Oficial: https://inside.fifa.com/fifa-world-ranking/men
B20: Puntos a completar | C20: 11 selecciones sin punto exacto cargado: Sudáfrica, Bosnia y Herzegovina, Haití, Curazao, Nueva Zelanda, Cabo Verde, Arabia Saudita, Irak, Uzbekistán, Jordania, Ghana. Completá desde la fuente FIFA del 19-nov-2025.
B21: Clasificatorias | C21: Wikipedia — 2026 FIFA World Cup qualification (por confederación) / RSSSF.
B22: Datos de país | C22: Población y PIB: Banco Mundial (data.worldbank.org). Valor de plantel: Transfermarkt.
B23: Nota | C23: El ranking del 19-nov-2025 es una foto previa al torneo (limpia de resultados del Mundial). Si preferís una más reciente, está la del 01-abr-2026 y 11-jun-2026 en la misma fuente.
B24: Historial | C24: Historial mundialista de las 48: apariciones (incl. 2026), debut, mejor resultado, títulos/subcampeonatos/3os puestos y récord histórico acumulado (PJ, PG, PE, PP, GF, GC hasta 2022). VERIFICADO.
B25: DTs | C25: Entrenador de cada selección: nombre, nacionalidad, año de asunción, cargo anterior y trayectoria. VERIFICADO (amarillo = cambio reciente a confirmar).

Sheet Selecciones
A1: Selecciones participantes — Mundial 2026
A2: N° | B2: País | C2: Cód. | D2: Grupo | E2: Pos. grupo | F2: Confederación | G2: Ranking FIFA (19-nov-25) | H2: Puntos FIFA (19-nov-25) | I2: Sede | J2: Debutante | K2: Títulos mundiales
A3: 1 | B3: México | C3: MEX | D3: A | E3: 1 | F3: CONCACAF | G3: 15 | H3: 1675.74 | I3: Sí | J3: No | K3: 0
A4: 2 | B4: Sudáfrica | C4: RSA | D4: A | E4: 2 | F4: CAF | G4: 61 | H4: 1427.3 | I4: No | J4: No | K4: 0
A5: 3 | B5: Corea del Sur | C5: KOR | D5: A | E5: 3 | F5: AFC | G5: 22 | H5: 1599.45 | I5: No | J5: No | K5: 0
A6: 4 | B6: Chequia | C6: CZE | D6: A | E6: 4 | F6: UEFA | G6: 44 | H6: 1487 | I6: No | J6: No | K6: 0
A7: 5 | B7: Canadá | C7: CAN | D7: B | E7: 1 | F7: CONCACAF | G7: 27 | H7: 1559.16 | I7: Sí | J7: No | K7: 0
A8: 6 | B8: Bosnia y Herzegovina | C8: BIH | D8: B | E8: 2 | F8: UEFA | G8: 71 | H8: 1393.9 | I8: No | J8: No | K8: 0
A9: 7 | B9: Catar | C9: QAT | D9: B | E9: 3 | F9: AFC | G9: 51 | H9: 1461.6 | I9: No | J9: No | K9: 0
A10: 8 | B10: Suiza | C10: SUI | D10: B | E10: 4 | F10: UEFA | G10: 17 | H10: 1654.69 | I10: No | J10: No | K10: 0
A11: 9 | B11: Brasil | C11: BRA | D11: C | E11: 1 | F11: CONMEBOL | G11: 5 | H11: 1760.46 | I11: No | J11: No | K11: 5
A12: 10 | B12: Marruecos | C12: MAR | D12: C | E12: 2 | F12: CAF | G12: 11 | H12: 1713.12 | I12: No | J12: No | K12: 0
A13: 11 | B13: Haití | C13: HAI | D13: C | E13: 3 | F13: CONCACAF | G13: 84 | H13: 1350.5 | I13: No | J13: No | K13: 0
A14: 12 | B14: Escocia | C14: SCO | D14: C | E14: 4 | F14: UEFA | G14: 36 | H14: 1506.77 | I14: No | J14: No | K14: 0
... A50: 48 | B50: Panamá | C50: PAN | D50: L | E50: 4 | F50: CONCACAF | G50: 30 | H50: 1540.42 | I50: No | J50: No | K50: 0
B52: Fuente ranking: FIFA/Coca-Cola 19-nov-2025 (foto del sorteo). Celdas amarillas = puntos a completar. Confederación, sede, debutante y títulos verificados.

Sheet Historial
A1: Historial mundialista por selección (apariciones incl. 2026; récord histórico acumulado hasta 2022)
A2: N° | B2: País | C2: Conf. | D2: Aparic. (incl. 2026) | E2: Debut | F2: Mejor resultado (hist.) | G2: Títulos | H2: Subcamp. | I2: 3er puesto | J2: PJ | K2: PG | L2: PE | M2: PP | N2: GF | O2: GC | P2: DG | Q2: Pts (3-1-0) | R2: % Vict.
A3: 1 | B3: México | C3: CONCACAF | D3: 18 | E3: 1930 | F3: Cuartos de final (1970, 1986) | G3: 0 | H3: 0 | I3: 0 | J3: 60 | K3: 17 | L3: 15 | M3: 28 | N3: 62 | O3: 101 | P3: =N3-O3 -> -39 | Q3: =3*K3+L3 -> 66 | R3: =IF(J3=0,"",K3/J3) -> 0.28333333
A4: 2 | B4: Sudáfrica | C4: CAF | D4: 4 | E4: 1998 | F4: Fase de grupos | G4: 0 | H4: 0 | I4: 0 | J4: 9 | K4: 2 | L4: 4 | M4: 3 | N4: 11 | O4: 16 | P4: =N4-O4 -> -5 | Q4: =3*K4+L4 -> 10 | R4: =IF(J4=0,"",K4/J4) -> 0.22222222
A5: 3 | B5: Corea del Sur | C5: AFC | D5: 12 | E5: 1954 | F5: Cuarto puesto (2002) | G5: 0 | H5: 0 | I5: 0 | J5: 38 | K5: 7 | L5: 10 | M5: 21 | N5: 39 | O5: 78 | P5: =N5-O5 -> -39 | Q5: =3*K5+L5 -> 31 | R5: =IF(J5=0,"",K5/J5) -> 0.18421053
A6: 4 | B6: Chequia | C6: UEFA | D6: 10 | E6: 1934 | F6: Subcampeón (1934, 1962) | G6: 0 | H6: 2 | I6: 0 | J6: 33 | K6: 12 | L6: 5 | M6: 16 | N6: 47 | O6: 49 | P6: =N6-O6 -> -2 | Q6: =3*K6+L6 -> 41 | R6: =IF(J6=0,"",K6/J6) -> 0.36363636
A7: 5 | B7: Canadá | C7: CONCACAF | D7: 3 | E7: 1986 | F7: Fase de grupos | G7: 0 | H7: 0 | I7: 0 | J7: 6 | K7: 0 | L7: 0 | M7: 6 | N7: 2 | O7: 12 | P7: =N7-O7 -> -10 | Q7: =3*K7+L7 -> 0 | R7: =IF(J7=0,"",K7/J7) -> 0
A8: 6 | B8: Bosnia y Herzegovina | C8: UEFA | D8: 2 | E8: 2014 | F8: Fase de grupos | G8: 0 | H8: 0 | I8: 0 | J8: 3 | K8: 1 | L8: 0 | M8: 2 | N8: 4 | O8: 4 | P8: =N8-O8 -> 0 | Q8: =3*K8+L8 -> 3 | R8: =IF(J8=0,"",K8/J8) -> 0.33333333
A9: 7 | B9: Catar | C9: AFC | D9: 2 | E9: 2022 | F9: Fase de grupos | G9: 0 | H9: 0 | I9: 0 | J9: 3 | K9: 0 | L9: 0 | M9: 3 | N9: 1 | O9: 7 | P9: =N9-O9 -> -6 | Q9: =3*K9+L9 -> 0 | R9: =IF(J9=0,"",K9/J9) -> 0
A10: 8 | B10: Suiza | C10: UEFA | D10: 13 | E10: 1934 | F10: Cuartos de final (1934, 1938, 1954) | G10: 0 | H10: 0 | I10: 0 | J10: 41 | K10: 14 | L10: 8 | M10: 19 | N10: 55 | O10: 73 | P10: =N10-O10 -> -18 | Q10: =3*K10+L10 -> 50 | R10: =IF(J10=0,"",K10/J10) -> 0.34146341
A11: 9 | B11: Brasil | C11: CONMEBOL | D11: 23 | E11: 1930 | F11: Campeón (1958, 1962, 1970, 1994, 2002) | G11: 5 | H11: 2 | I11: 2 | J11: 114 | K11: 76 | L11: 19 | M11: 19 | N11: 237 | O11: 108 | P11: =N11-O11 -> 129 | Q11: =3*K11+L11 -> 247 | R11: =IF(J11=0,"",K11/J11) -> 0.66666667
A12: 10 | B12: Marruecos | C12: CAF | D12: 7 | E12: 1970 | F12: Cuarto puesto (2022) | G12: 0 | H12: 0 | I12: 0 | J12: 23 | K12: 5 | L12: 7 | M12: 11 | N12: 20 | O12: 27 | P12: =N12-O12 -> -7 | Q12: =3*K12+L12 -> 22 | R12: =IF(J12=0,"",K12/J12) -> 0.2173913
A13: 11 | B13: Haití | C13: CONCACAF | D13: 2 | E13: 1974 | F13: Fase de grupos | G13: 0 | H13: 0 | I13: 0 | J13: 3 | K13: 0 | L13: 0 | M13: 3 | N13: 2 | O13: 14 | P13: =N13-O13 -> -12 | Q13: =3*K13+L13 -> 0 | R13: =IF(J13=0,"",K13/J13) -> 0
A14: 12 | B14: Escocia | C14: UEFA | D14: 9 | E14: 1954 | F14: Fase de grupos | G14: 0 | H14: 0 | I14: 0 | J14: 23 | K14: 4 | L14: 7 | M14: 12 | N14: 25 | O14: 41 | P14: =N14-O14 -> -16 | Q14: =3*K14+L14 -> 19 | R14: =IF(J14=0,"",K14/J14) -> 0.17391304
... A50: 48 | B50: Panamá | C50: CONCACAF | D50: 2 | E50: 2018 | F50: Fase de grupos | G50: 0 | H50: 0 | I50: 0 | J50: 3 | K50: 0 | L50: 0 | M50: 3 | N50: 2 | O50: 11 | P50: =N50-O50 -> -9 | Q50: =3*K50+L50 -> 0 | R50: =IF(J50=0,"",K50/J50) -> 0
B52: Apariciones incluyen 2026 (corregidas para Suecia, Bosnia, Turquía, Chequia, RD Congo e Irak, que clasificaron por repechaje en marzo-2026). Récord histórico (PJ…Pts) acumulado en fases finales hasta el Mundial 2022, no incluye 2026. Chequia incluye a Checoslovaquia; RD Congo incluye a Zaire (1974); Alemania incluye a Alemania Occidental. Fuente: Wikipedia 'National team appearances in the FIFA World Cup' (consultado 24-jun-2026).

Sheet DTs
A1: Entrenadores (DT) — Mundial 2026
A2: N° | B2: País | C2: Director técnico | D2: Nacionalidad | E2: En el cargo desde | F2: Cargo anterior | G2: Trayectoria / notas | H2: Punt. selección (0-50) | I2: Punt. clubes (0-50) | J2: Puntaje DT (0-100)
A3: 1 | B3: México | C3: Javier Aguirre | D3: México | E3: 2024 | F3: DT Mallorca | G3: Tercera etapa en México; dirigió en los Mundiales 1994, 2002 y 2010 | H3: 24 | I3: 22 | J3: 46
A4: 2 | B4: Sudáfrica | C4: Hugo Broos | D4: Bélgica | E4: 2021 | F4: DT KV Oostende | G4: Campeón de la Copa Africana 2017 con Camerún | H4: 30 | I4: 10 | J4: 40
A5: 3 | B5: Corea del Sur | C5: Hong Myung-bo | D5: Corea del Sur | E5: 2024 | F5: DT Ulsan HD | G5: Exjugador; dirigió a Corea en el Mundial 2014 | H5: 18 | I5: 12 | J5: 30
A6: 4 | B6: Chequia | C6: Miroslav Koubek | D6: Chequia | E6: 2024 | F6: DT Viktoria Plzeň | H6: 8 | I6: 12 | J6: 20
A7: 5 | B7: Canadá | C7: Jesse Marsch | D7: Estados Unidos | E7: 2024 | F7: DT Leeds United | G7: Ex RB Leipzig y RB Salzburg | H7: 14 | I7: 22 | J7: 36
A8: 6 | B8: Bosnia y Herzegovina | C8: Sergej Barbarez | D8: Bosnia y Herzegovina | E8: 2024 | F8: Exjugador / comentarista | G8: Primer cargo importante como DT | H8: 6 | I8: 6 | J8: 12
A9: 7 | B9: Catar | C9: Julen Lopetegui | D9: España | E9: 2025 | F9: DT West Ham | G9: Exseleccionador de España; ex DT Real Madrid y Sevilla | H9: 18 | I9: 30 | J9: 48
A10: 8 | B10: Suiza | C10: Murat Yakin | D10: Suiza | E10: 2021 | F10: DT Schaffhausen | H10: 20 | I10: 16 | J10: 36
A11: 9 | B11: Brasil | C11: Carlo Ancelotti | D11: Italia | E11: 2025 | F11: DT Real Madrid | G11: 5 Champions League como DT (récord); primer Mundial como entrenador | H11: 8 | I11: 50 | J11: 58
A12: 10 | B12: Marruecos | C12: Mohamed Ouahbi | D12: Marruecos | E12: 2026 | F12: DT Marruecos sub-20 | G12: Campeón del Mundial sub-20 2025; asumió tras la Copa Africana 2025 | H12: 12 | I12: 8 | J12: 20
A13: 11 | B13: Haití | C13: Sébastien Migné | D13: Francia | E13: 2024 | F13: Asistente de Camerún | G13: Clasificó a Haití sin pisar el país por el conflicto interno | H13: 12 | I13: 6 | J13: 18
A14: 12 | B14: Escocia | C14: Steve Clarke | D14: Escocia | E14: 2019 | F14: DT Kilmarnock | G14: Ex asistente de Mourinho en Chelsea | H14: 22 | I14: 14 | J14: 36
A15: 13 | B15: Estados Unidos | C15: Mauricio Pochettino | D15: Argentina | E15: 2024 | F15: DT Chelsea | G15: Ex Tottenham y PSG | H15: 12 | I15: 36 | J15: 48
A16: 14 | B16: Paraguay | C16: Gustavo Alfaro | D16: Argentina | E16: 2024 | F16: DT selección de Costa Rica | H16: 24 | I16: 20 | J16: 44
A17: 15 | B17: Australia | C17: Tony Popovic | D17: Australia | E17: 2024 | F17: DT Melbourne Victory | H17: 16 | I17: 16 | J17: 32
A18: 16 | B18: Turquía | C18: Vincenzo Montella | D18: Italia | E18: 2023 | F18: DT Adana Demirspor | G18: Exjugador de Roma; ex DT Milan y Fiorentina | H18: 16 | I18: 22 | J18: 38
A19: 17 | B19: Alemania | C19: Julian Nagelsmann | D19: Alemania | E19: 2023 | F19: DT Bayern Múnich | G19: Ex RB Leipzig | H19: 22 | I19: 30 | J19: 52
A20: 18 | B20: Curazao | C20: Dick Advocaat | D20: Países Bajos | E20: 2024 | F20: DT ADO Den Haag | G20: Veterano; dirigió múltiples selecciones (Países Bajos, Rusia, etc.) | H20: 30 | I20: 26 | J20: 56
A21: 19 | B21: Costa de Marfil | C21: Emerse Faé | D21: Costa de Marfil | E21: 2024 | F21: Asistente de Costa de Marfil | G21: Campeón de la Copa Africana 2023 | H21: 26 | I21: 6 | J21: 32
A22: 20 | B22: Ecuador | C22: Sebastián Beccacece | D22: Argentina | E22: 2024 | F22: DT Elche | H22: 16 | I22: 16 | J22: 32
A23: 21 | B23: Países Bajos | C23: Ronald Koeman | D23: Países Bajos | E23: 2023 | F23: DT selección Países Bajos (1ª etapa) | G23: Único en jugar y dirigir a Ajax, PSV y Feyenoord | H23: 26 | I23: 30 | J23: 56
A24: 22 | B24: Japón | C24: Hajime Moriyasu | D24: Japón | E24: 2018 | F24: DT Japón sub-23 | G24: Dirigió a Japón en el Mundial 2022 | H24: 24 | I24: 14 | J24: 38
A25: 23 | B25: Suecia | C25: Graham Potter | D25: Inglaterra | E25: 2025 | F25: DT Chelsea | G25: Ex Brighton | H25: 8 | I25: 22 | J25: 30
A26: 24 | B26: Túnez | C26: Sami Trabelsi | D26: Túnez | E26: 2025 | F26: DT Al-Sailiya | G26: Cambio reciente en el banco tunecino | H26: 14 | I26: 8 | J26: 22
A27: 25 | B27: Bélgica | C27: Rudi Garcia | D27: Francia | E27: 2025 | F27: DT Napoli | G27: Ex Roma, Marsella y Lyon | H27: 8 | I27: 30 | J27: 38
A28: 26 | B28: Egipto | C28: Hossam Hassan | D28: Egipto | E28: 2024 | F28: DT Modern Future | G28: Máximo goleador histórico de Egipto como jugador | H28: 16 | I28: 14 | J28: 30
A29: 27 | B29: Irán | C29: Amir Ghalenoei | D29: Irán | E29: 2023 | F29: DT Gol Gohar | G29: Segunda etapa al frente de Irán | H29: 18 | I29: 14 | J29: 32
A30: 28 | B30: Nueva Zelanda | C30: Darren Bazeley | D30: Inglaterra | E30: 2023 | F30: DT Nueva Zelanda sub-23 | H30: 10 | I30: 6 | J30: 16
A31: 29 | B31: España | C31: Luis de la Fuente | D31: España | E31: 2022 | F31: DT España sub-21 | G31: Campeón de la UEFA Nations League 2023 y la Euro 2024 | H31: 34 | I31: 6 | J31: 40
A32: 30 | B32: Cabo Verde | C32: Pedro Brito 'Bubista' | D32: Cabo Verde | E32: 2020 | F32: DT de clubes | G32: Clasificó a Cabo Verde a su primer Mundial | H32: 14 | I32: 6 | J32: 20
A33: 31 | B33: Arabia Saudita | C33: Giorgos Donis | D33: Grecia | E33: 2025 | F33: DT Al-Fateh | G33: Asumió en abril-2026 en reemplazo de Hervé Renard | H33: 8 | I33: 14 | J33: 22
A34: 32 | B34: Uruguay | C34: Marcelo Bielsa | D34: Argentina | E34: 2023 | F34: DT Leeds United | G34: Exseleccionador de Argentina y Chile | H34: 30 | I34: 26 | J34: 56
A35: 33 | B35: Francia | C35: Didier Deschamps | D35: Francia | E35: 2012 | F35: DT Marsella | G35: Campeón del Mundial 2018 y finalista 2022; última competencia en el cargo | H35: 50 | I35: 28 | J35: 78
A36: 34 | B36: Senegal | C36: Pape Thiaw | D36: Senegal | E36: 2024 | F36: Asistente de Senegal | H36: 12 | I36: 8 | J36: 20
A37: 35 | B37: Irak | C37: Graham Arnold | D37: Australia | E37: 2025 | F37: DT selección de Australia | G37: Dos etapas al frente de Australia | H37: 20 | I37: 14 | J37: 34
A38: 36 | B38: Noruega | C38: Ståle Solbakken | D38: Noruega | E38: 2020 | F38: DT FC Copenhague | H38: 18 | I38: 20 | J38: 38
A39: 37 | B39: Argentina | C39: Lionel Scaloni | D39: Argentina | E39: 2018 | F39: Asistente de Argentina | G39: Campeón del Mundial 2022 y de la Copa América 2021 y 2024 | H39: 48 | I39: 4 | J39: 52
A40: 38 | B40: Argelia | C40: Vladimir Petković | D40: Bosnia y Herzegovina | E40: 2024 | F40: DT selección de Suiza | G40: Ex DT de Lazio y Burdeos | H40: 26 | I40: 18 | J40: 44
...

Sheet Clasificatorias
A1: Clasificatorias / Eliminatorias — rendimiento por selección (cargá PJ, PG, PE, PP, GF, GC)
A2: N° | B2: País | C2: Confederación | D2: PJ | E2: PG | F2: PE | G2: PP | H2: GF | I2: GC | J2: Pts | K2: DG | L2: % Pts | M2: GF/PJ | N2: GC/PJ | O2: Dificultad conf. | P2: Puntaje clasif. ponderado
A3: 1 | B3: México | C3: CONCACAF | J3: =IF(COUNT(D3:G3)=0,"",3*E3+F3) | K3: =IF(COUNT(H3:I3)=0,"",H3-I3) | L3: =IF(N(D3)=0,"",(3*E3+F3)/(D3*3)) | M3: =IF(N(D3)=0,"",H3/D3) | N3: =IF(N(D3)=0,"",I3/D3) | O3: 0.5 | P3: 35
A4: 2 | B4: Sudáfrica | C4: CAF | D4: 10 | E4: 6 | F4: 2 | G4: 2 | H4: 14 | I4: 8 | J4: =IF(COUNT(D4:G4)=0,"",3*E4+F4) -> 20 | K4: =IF(COUNT(H4:I4)=0,"",H4-I4) -> 6 | L4: =IF(N(D4)=0,"",(3*E4+F4)/(D4*3)) -> 0.66666667 | M4: =IF(N(D4)=0,"",H4/D4) -> 1.4 | N4: =IF(N(D4)=0,"",I4/D4) -> 0.8 | O4: 0.52 | P4: 34.7
A5: 3 | B5: Corea del Sur | C5: AFC | D5: 10 | E5: 7 | F5: 3 | G5: 0 | H5: 20 | I5: 6 | J5: =IF(COUNT(D5:G5)=0,"",3*E5+F5) -> 24 | K5: =IF(COUNT(H5:I5)=0,"",H5-I5) -> 14 | L5: =IF(N(D5)=0,"",(3*E5+F5)/(D5*3)) -> 0.8 | M5: =IF(N(D5)=0,"",H5/D5) -> 2 | N5: =IF(N(D5)=0,"",I5/D5) -> 0.6 | O5: 0.48 | P5: 38.4
A6: 4 | B6: Chequia | C6: UEFA | D6: 8 | E6: 5 | F6: 1 | G6: 2 | H6: 14 | I6: 9 | J6: =IF(COUNT(D6:G6)=0,"",3*E6+F6) -> 16 | K6: =IF(COUNT(H6:I6)=0,"",H6-I6) -> 5 | L6: =IF(N(D6)=0,"",(3*E6+F6)/(D6*3)) -> 0.66666667 | M6: =IF(N(D6)=0,"",H6/D6) -> 1.75 | N6: =IF(N(D6)=0,"",I6/D6) -> 1.125 | O6: 1 | P6: 66.7
A7: 5 | B7: Canadá | C7: CONCACAF | J7: =IF(COUNT(D7:G7)=0,"",3*E7+F7) | K7: =IF(COUNT(H7:I7)=0,"",H7-I7) | L7: =IF(N(D7)=0,"",(3*E7+F7)/(D7*3)) | M7: =IF(N(D7)=0,"",H7/D7) | N7: =IF(N(D7)=0,"",I7/D7) | O7: 0.5 | P7: 35
A8: 6 | B8: Bosnia y Herzegovina | C8: UEFA | D8: 8 | E8: 5 | F8: 2 | G8: 1 | H8: 14 | I8: 8 | J8: =IF(COUNT(D8:G8)=0,"",3*E8+F8) -> 17 | K8: =IF(COUNT(H8:I8)=0,"",H8-I8) -> 6 | L8: =IF(N(D8)=0,"",(3*E8+F8)/(D8*3)) -> 0.70833333 | M8: =IF(N(D8)=0,"",H8/D8) -> 1.75 | N8: =IF(N(D8)=0,"",I8/D8) -> 1 | O8: 1 | P8: 70.8
A9: 7 | B9: Catar | C9: AFC | D9: 10 | E9: 6 | F9: 2 | G9: 2 | H9: 16 | I9: 9 | J9: =IF(COUNT(D9:G9)=0,"",3*E9+F9) -> 20 | K9: =IF(COUNT(H9:I9)=0,"",H9-I9) -> 7 | L9: =IF(N(D9)=0,"",(3*E9+F9)/(D9*3)) -> 0.66666667 | M9: =IF(N(D9)=0,"",H9/D9) -> 1.6 | N9: =IF(N(D9)=0,"",I9/D9) -> 0.9 | O9: 0.48 | P9: 32
A10: 8 | B10: Suiza | C10: UEFA | D10: 8 | E10: 5 | F10: 3 | G10: 0 | H10: 15 | I10: 6 | J10: =IF(COUNT(D10:G10)=0,"",3*E10+F10) -> 18 | K10: =IF(COUNT(H10:I10)=0,"",H10-I10) -> 9 | L10: =IF(N(D10)=0,"",(3*E10+F10)/(D10*3)) -> 0.75 | M10: =IF(N(D10)=0,"",H10/D10) -> 1.875 | N10: =IF(N(D10)=0,"",I10/D10) -> 0.75 | O10: 1 | P10: 75
A11: 9 | B11: Brasil | C11: CONMEBOL | D11: 18 | E11: 8 | F11: 4 | G11: 6 | H11: 24 | I11: 18 | J11: =IF(COUNT(D11:G11)=0,"",3*E11+F11) -> 28 | K11: =IF(COUNT(H11:I11)=0,"",H11-I11) -> 6 | L11: =IF(N(D11)=0,"",(3*E11+F11)/(D11*3)) -> 0.51851852 | M11: =IF(N(D11)=0,"",H11/D11) -> 1.3333333 | N11: =IF(N(D11)=0,"",I11/D11) -> 1 | O11: 0.95 | P11: 49.3
A12: 10 | B12: Marruecos | C12: CAF | D12: 10 | E12: 8 | F12: 1 | G12: 1 | H12: 20 | I12: 5 | J12: =IF(COUNT(D12:G12)=0,"",3*E12+F12) -> 25 | K12: =IF(COUNT(H12:I12)=0,"",H12-I12) -> 15 | L12: =IF(N(D12)=0,"",(3*E12+F12)/(D12*3)) -> 0.83333333 | M12: =IF(N(D12)=0,"",H12/D12) -> 2 | N12: =IF(N(D12)=0,"",I12/D12) -> 0.5 | O12: 0.52 | P12: 43.3
A13: 11 | B13: Haití | C13: CONCACAF | D13: 10 | E13: 5 | F13: 2 | G13: 3 | H13: 12 | I13: 10 | J13: =IF(COUNT(D13:G13)=0,"",3*E13+F13) -> 17 | K13: =IF(COUNT(H13:I13)=0,"",H13-I13) -> 2 | L13: =IF(N(D13)=0,"",(3*E13+F13)/(D13*3)) -> 0.56666667 | M13: =IF(N(D13)=0,"",H13/D13) -> 1.2 | N13: =IF(N(D13)=0,"",I13/D13) -> 1 | O13: 0.5 | P13: 28.3
A14: 12 | B14: Escocia | C14: UEFA | D14: 8 | E14: 5 | F14: 2 | G14: 1 | H14: 12 | I14: 8 | J14: =IF(COUNT(D14:G14)=0,"",3*E14+F14) -> 17 | K14: =IF(COUNT(H14:I14)=0,"",H14-I14) -> 4 | L14: =IF(N(D14)=0,"",(3*E14+F14)/(D14*3)) -> 0.70833333 | M14: =IF(N(D14)=0,"",H14/D14) -> 1.5 | N14: =IF(N(D14)=0,"",I14/D14) -> 1 | O14: 1 | P14: 70.8
A15: 13 | B15: Estados Unidos | C15: CONCACAF | J15: =IF(COUNT(D15:G15)=0,"",3*E15+F15) | K15: =IF(COUNT(H15:I15)=0,"",H15-I15) | L15: =IF(N(D15)=0,"",(3*E15+F15)/(D15*3)) | M15: =IF(N(D15)=0,"",H15/D15) | N15: =IF(N(D15)=0,"",I15/D15) | O15: 0.5 | P15: 35
A16: 14 | B16: Paraguay | C16: CONMEBOL | D16: 18 | E16: 7 | F16: 7 | G16: 4 | H16: 14 | I16: 10 | J16: =IF(COUNT(D16:G16)=0,"",3*E16+F16) -> 28 | K16: =IF(COUNT(H16:I16)=0,"",H16-I16) -> 4 | L16: =IF(N(D16)=0,"",(3*E16+F16)/(D16*3)) -> 0.51851852 | M16: =IF(N(D16)=0,"",H16/D16) -> 0.77777778 | N16: =IF(N(D16)=0,"",I16/D16) -> 0.55555556 | O16: 0.95 | P16: 49.3
A17: 15 | B17: Australia | C17: AFC | D17: 10 | E17: 6 | F17: 3 | G17: 1 | H17: 16 | I17: 8 | J17: =IF(COUNT(D17:G17)=0,"",3*E17+F17) -> 21 | K17: =IF(COUNT(H17:I17)=0,"",H17-I17) -> 8 | L17: =IF(N(D17)=0,"",(3*E17+F17)/(D17*3)) -> 0.7 | M17: =IF(N(D17)=0,"",H17/D17) -> 1.6 | N17: =IF(N(D17)=0,"",I17/D17) -> 0.8 | O17: 0.48 | P17: 33.6
A18: 16 | B18: Turquía | C18: UEFA | D18: 8 | E18: 5 | F18: 2 | G18: 1 | H18: 16 | I18: 9 | J18: =IF(COUNT(D18:G18)=0,"",3*E18+F18) -> 17 | K18: =IF(COUNT(H18:I18)=0,"",H18-I18) -> 7 | L18: =IF(N(D18)=0,"",(3*E18+F18)/(D18*3)) -> 0.70833333 | M18: =IF(N(D18)=0,"",H18/D18) -> 2 | N18: =IF(N(D18)=0,"",I18/D18) -> 1.125 | O18: 1 | P18: 70.8
A19: 17 | B19: Alemania | C19: UEFA | D19: 8 | E19: 6 | F19: 1 | G19: 1 | H19: 18 | I19: 7 | J19: =IF(COUNT(D19:G19)=0,"",3*E19+F19) -> 19 | K19: =IF(COUNT(H19:I19)=0,"",H19-I19) -> 11 | L19: =IF(N(D19)=0,"",(3*E19+F19)/(D19*3)) -> 0.79166667 | M19: =IF(N(D19)=0,"",H19/D19) -> 2.25 | N19: =IF(N(D19)=0,"",I19/D19) -> 0.875 | O19: 1 | P19: 79.2
A20: 18 | B20: Curazao | C20: CONCACAF | D20: 10 | E20: 4 | F20: 4 | G20: 2 | H20: 12 | I20: 9 | J20: =IF(COUNT(D20:G20)=0,"",3*E20+F20) -> 16 | K20: =IF(COUNT(H20:I20)=0,"",H20-I20) -> 3 | L20: =IF(N(D20)=0,"",(3*E20+F20)/(D20*3)) -> 0.53333333 | M20: =IF(N(D20)=0,"",H20/D20) -> 1.2 | N20: =IF(N(D20)=0,"",I20/D20) -> 0.9 | O20: 0.5 | P20: 26.7
A21: 19 | B21: Costa de Marfil | C21: CAF | D21: 10 | E21: 6 | F21: 2 | G21: 2 | H21: 16 | I21: 8 | J21: =IF(COUNT(D21:G21)=0,"",3*E21+F21) -> 20 | K21: =IF(COUNT(H21:I21)=0,"",H21-I21) -> 8 | L21: =IF(N(D21)=0,"",(3*E21+F21)/(D21*3)) -> 0.66666667 | M21: =IF(N(D21)=0,"",H21/D21) -> 1.6 | N21: =IF(N(D21)=0,"",I21/D21) -> 0.8 | O21: 0.52 | P21: 34.7
A22: 20 | B22: Ecuador | C22: CONMEBOL | D22: 18 | E22: 7 | F22: 4 | G22: 7 | H22: 18 | I22: 14 | J22: =IF(COUNT(D22:G22)=0,"",3*E22+F22) -> 25 | K22: =IF(COUNT(H22:I22)=0,"",H22-I22) -> 4 | L22: =IF(N(D22)=0,"",(3*E22+F22)/(D22*3)) -> 0.46296296 | M22: =IF(N(D22)=0,"",H22/D22) -> 1 | N22: =IF(N(D22)=0,"",I22/D22) -> 0.77777778 | O22: 0.95 | P22: 44
A23: 21 | B23: Países Bajos | C23: UEFA | D23: 8 | E23: 6 | F23: 2 | G23: 0 | H23: 19 | I23: 8 | J23: =IF(COUNT(D23:G23)=0,"",3*E23+F23) -> 20 | K23: =IF(COUNT(H23:I23)=0,"",H23-I23) -> 11 | L23: =IF(N(D23)=0,"",(3*E23+F23)/(D23*3)) -> 0.83333333 | M23: =IF(N(D23)=0,"",H23/D23) -> 2.375 | N23: =IF(N(D23)=0,"",I23/D23) -> 1 | O23: 1 | P23: 83.3
A24: 22 | B24: Japón | C24: AFC | D24: 10 | E24: 8 | F24: 2 | G24: 0 | H24: 26 | I24: 4 | J24: =IF(COUNT(D24:G24)=0,"",3*E24+F24) -> 26 | K24: =IF(COUNT(H24:I24)=0,"",H24-I24) -> 22 | L24: =IF(N(D24)=0,"",(3*E24+F24)/(D24*3)) -> 0.86666667 | M24: =IF(N(D24)=0,"",H24/D24) -> 2.6 | N24: =IF(N(D24)=0,"",I24/D24) -> 0.4 | O24: 0.48 | P24: 41.6
A25: 23 | B25: Suecia | C25: UEFA | D25: 8 | E25: 4 | F25: 2 | G25: 2 | H25: 14 | I25: 10 | J25: =IF(COUNT(D25:G25)=0,"",3*E25+F25) -> 14 | K25: =IF(COUNT(H25:I25)=0,"",H25-I25) -> 4 | L25: =IF(N(D25)=0,"",(3*E25+F25)/(D25*3)) -> 0.58333333 | M25: =IF(N(D25)=0,"",H25/D25) -> 1.75 | N25: =IF(N(D25)=0,"",I25/D25) -> 1.25 | O25: 1 | P25: 58.3
A26: 24 | B26: Túnez | C26: CAF | D26: 10 | E26: 6 | F26: 3 | G26: 1 | H26: 12 | I26: 2 | J26: =IF(COUNT(D26:G26)=0,"",3*E26+F26) -> 21 | K26: =IF(COUNT(H26:I26)=0,"",H26-I26) -> 10 | L26: =IF(N(D26)=0,"",(3*E26+F26)/(D26*3)) -> 0.7 | M26: =IF(N(D26)=0,"",H26/D26) -> 1.2 | N26: =IF(N(D26)=0,"",I26/D26) -> 0.2 | O26: 0.52 | P26: 36.4
A27: 25 | B27: Bélgica | C27: UEFA | D27: 8 | E27: 5 | F27: 3 | G27: 0 | H27: 20 | I27: 9 | J27: =IF(COUNT(D27:G27)=0,"",3*E27+F27) -> 18 | K27: =IF(COUNT(H27:I27)=0,"",H27-I27) -> 11 | L27: =IF(N(D27)=0,"",(3*E27+F27)/(D27*3)) -> 0.75 | M27: =IF(N(D27)=0,"",H27/D27) -> 2.5 | N27: =IF(N(D27)=0,"",I27/D27) -> 1.125 | O27: 1 | P27: 75
... A50: 48 | B50: Panamá | C50: CONCACAF | D50: 10 | E50: 5 | F50: 3 | G50: 2 | H50: 14 | I50: 9 | J50: =IF(COUNT(D50:G50)=0,"",3*E50+F50) -> 18 | K50: =IF(COUNT(H50:I50)=0,"",H50-I50) -> 5 | L50: =IF(N(D50)=0,"",(3*E50+F50)/(D50*3)) -> 0.6 | M50: =IF(N(D50)=0,"",H50/D50) -> 1.4 | N50: =IF(N(D50)=0,"",I50/D50) -> 0.9 | O50: 0.5 | P50: 30
B52: Cargá PJ/PG/PE/PP/GF/GC (amarillo). Pts=3·PG+PE; %Pts=Pts/(PJ·3). Fuente sugerida: Wikipedia 2026 FIFA World Cup qualification (por confederación) / RSSSF.

Sheet Predictores_país
A1: Predictores de país / plantel (plantilla — cargá tus datos)
A2: N° | B2: País | C2: Cód. | D2: Población | E2: PIB (USD MM) | F2: PIB per cápita (USD) | G2: Valor plantel (€ MM) | H2: Edad prom. plantel | I2: Jug. en top-5 ligas | J2: Año de referencia
A3: 1 | B3: México | C3: MEX | G3: 191.85 | H3: 27.5 | I3: 6 | J3: 2026
A4: 2 | B4: Sudáfrica | C4: RSA | G4: 49.25 | H4: 26.35 | I4: 4 | J4: 2026
A5: 3 | B5: Corea del Sur | C5: KOR | G5: 139.05 | H5: 27.46 | I5: 8 | J5: 2026
A6: 4 | B6: Chequia | C6: CZE | G6: 188.18 | H6: 27.23 | I6: 9 | J6: 2026
A7: 5 | B7: Canadá | C7: CAN | G7: 198.65 | H7: 26.42 | I7: 12 | J7: 2026
A8: 6 | B8: Bosnia y Herzegovina | C8: BIH | G8: 146.4 | H8: 25.92 | I8: 13 | J8: 2026
A9: 7 | B9: Catar | C9: QAT | G9: 19.93 | H9: 28.92 | I9: 0 | J9: 2026
A10: 8 | B10: Suiza | C10: SUI | G10: 332.5 | H10: 27.81 | I10: 17 | J10: 2026
A11: 9 | B11: Brasil | C11: BRA | G11: 928.2 | H11: 28.65 | I11: 21 | J11: 2026
A12: 10 | B12: Marruecos | C12: MAR | G12: 447.7 | H12: 25.92 | I12: 19 | J12: 2026
A13: 11 | B13: Haití | C13: HAI | G13: 55.9 | H13: 27.08 | I13: 6 | J13: 2026
A14: 12 | B14: Escocia | C14: SCO | G14: 170.25 | H14: 28.73 | I14: 13 | J14: 2026
... A50: 48 | B50: Panamá | C50: PAN | G50: 34.55 | H50: 30 | I50: 3 | J50: 2026
B52: Fuentes sugeridas — Población y PIB: Banco Mundial (data.worldbank.org). Valor de plantel y datos de jugadores: Transfermarkt. Anotá el año de referencia para mantener consistencia.

Sheet Fixture_Grupos
A1: Fixture fase de grupos — cargá Goles A y Goles B (azul)
A2: ID | B2: Grupo | C2: Jornada | D2: Equipo A | E2: Equipo B | F2: Goles A | G2: Goles B | H2: Jugado | I2: Pts A | J2: Pts B | K2: Sede
A3: 1 | B3: A | C3: 1 | D3: México | E3: Sudáfrica | F3: 2 | G3: 0 | H3: =IF(AND(ISNUMBER(F3),ISNUMBER(G3)),1,0) -> 1 | I3: =IF(H3=1,IF(F3>G3,3,IF(F3=G3,1,0)),"") -> 3 | J3: =IF(H3=1,IF(G3>F3,3,IF(F3=G3,1,0)),"") -> 0
A4: 2 | B4: A | C4: 1 | D4: Corea del Sur | E4: Chequia | F4: 2 | G4: 1 | H4: =IF(AND(ISNUMBER(F4),ISNUMBER(G4)),1,0) -> 1 | I4: =IF(H4=1,IF(F4>G4,3,IF(F4=G4,1,0)),"") -> 3 | J4: =IF(H4=1,IF(G4>F4,3,IF(F4=G4,1,0)),"") -> 0
A5: 3 | B5: A | C5: 2 | D5: México | E5: Corea del Sur | F5: 1 | G5: 0 | H5: =IF(AND(ISNUMBER(F5),ISNUMBER(G5)),1,0) -> 1 | I5: =IF(H5=1,IF(F5>G5,3,IF(F5=G5,1,0)),"") -> 3 | J5: =IF(H5=1,IF(G5>F5,3,IF(F5=G5,1,0)),"") -> 0
A6: 4 | B6: A | C6: 2 | D6: Sudáfrica | E6: Chequia | F6: 1 | G6: 1 | H6: =IF(AND(ISNUMBER(F6),ISNUMBER(G6)),1,0) -> 1 | I6: =IF(H6=1,IF(F6>G6,3,IF(F6=G6,1,0)),"") -> 1 | J6: =IF(H6=1,IF(G6>F6,3,IF(F6=G6,1,0)),"") -> 1
A7: 5 | B7: A | C7: 3 | D7: México | E7: Chequia | F7: 3 | G7: 0 | H7: =IF(AND(ISNUMBER(F7),ISNUMBER(G7)),1,0) -> 1 | I7: =IF(H7=1,IF(F7>G7,3,IF(F7=G7,1,0)),"") -> 3 | J7: =IF(H7=1,IF(G7>F7,3,IF(F7=G7,1,0)),"") -> 0
A8: 6 | B8: A | C8: 3 | D8: Sudáfrica | E8: Corea del Sur | F8: 1 | G8: 0 | H8: =IF(AND(ISNUMBER(F8),ISNUMBER(G8)),1,0) -> 1 | I8: =IF(H8=1,IF(F8>G8,3,IF(F8=G8,1,0)),"") -> 3 | J8: =IF(H8=1,IF(G8>F8,3,IF(F8=G8,1,0)),"") -> 0
A9: 7 | B9: B | C9: 1 | D9: Canadá | E9: Bosnia y Herzegovina | F9: 1 | G9: 1 | H9: =IF(AND(ISNUMBER(F9),ISNUMBER(G9)),1,0) -> 1 | I9: =IF(H9=1,IF(F9>G9,3,IF(F9=G9,1,0)),"") -> 1 | J9: =IF(H9=1,IF(G9>F9,3,IF(F9=G9,1,0)),"") -> 1
A10: 8 | B10: B | C10: 1 | D10: Catar | E10: Suiza | F10: 1 | G10: 1 | H10: =IF(AND(ISNUMBER(F10),ISNUMBER(G10)),1,0) -> 1 | I10: =IF(H10=1,IF(F10>G10,3,IF(F10=G10,1,0)),"") -> 1 | J10: =IF(H10=1,IF(G10>F10,3,IF(F10=G10,1,0)),"") -> 1
A11: 9 | B11: B | C11: 2 | D11: Canadá | E11: Catar | F11: 6 | G11: 0 | H11: =IF(AND(ISNUMBER(F11),ISNUMBER(G11)),1,0) -> 1 | I11: =IF(H11=1,IF(F11>G11,3,IF(F11=G11,1,0)),"") -> 3 | J11: =IF(H11=1,IF(G11>F11,3,IF(F11=G11,1,0)),"") -> 0
A12: 10 | B12: B | C12: 2 | D12: Bosnia y Herzegovina | E12: Suiza | F12: 1 | G12: 4 | H12: =IF(AND(ISNUMBER(F12),ISNUMBER(G12)),1,0) -> 1 | I12: =IF(H12=1,IF(F12>G12,3,IF(F12=G12,1,0)),"") -> 0 | J12: =IF(H12=1,IF(G12>F12,3,IF(F12=G12,1,0)),"") -> 3
A13: 11 | B13: B | C13: 3 | D13: Canadá | E13: Suiza | F13: 1 | G13: 2 | H13: =IF(AND(ISNUMBER(F13),ISNUMBER(G13)),1,0) -> 1 | I13: =IF(H13=1,IF(F13>G13,3,IF(F13=G13,1,0)),"") -> 0 | J13: =IF(H13=1,IF(G13>F13,3,IF(F13=G13,1,0)),"") -> 3
A14: 12 | B14: B | C14: 3 | D14: Bosnia y Herzegovina | E14: Catar | F14: 3 | G14: 1 | H14: =IF(AND(ISNUMBER(F14),ISNUMBER(G14)),1,0) -> 1 | I14: =IF(H14=1,IF(F14>G14,3,IF(F14=G14,1,0)),"") -> 3 | J14: =IF(H14=1,IF(G14>F14,3,IF(F14=G14,1,0)),"") -> 0
... A74: 72 | B74: L | C74: 3 | D74: Croacia | E74: Ghana | F74: 2 | G74: 1 | H74: =IF(AND(ISNUMBER(F74),ISNUMBER(G74)),1,0) -> 1 | I74: =IF(H74=1,IF(F74>G74,3,IF(F74=G74,1,0)),"") -> 3 | J74: =IF(H74=1,IF(G74>F74,3,IF(F74=G74,1,0)),"") -> 0

Sheet Posiciones
A1: Tabla de posiciones — se calcula sola desde Fixture_Grupos
A2: Grupo | B2: Pos | C2: País | D2: PJ | E2: PG | F2: PE | G2: PP | H2: GF | I2: GC | J2: DG | K2: Pts | L2: Orden prov.
A3: A | B3: 1 | C3: México | D3: =SUMPRODUCT((Fixture_Grupos!$D$3:$D$74=$C3)*Fixture_Grupos!$H$3:$H$74)+SUMPRODUCT((Fixture_Grupos!$E$3:$E$74=$C3)*Fixture_Grupos!$H$3:$H$74) -> 3 | E3: =SUMPRODUCT((Fixture_Grupos!$D$3:$D$74=$C3)*Fixture_Grupos!$H$3:$H$74*(Fixture_Grupos!$F$3:$F$74>Fixture_Grupos!$G$3:$G$74))+SUMPRODUCT((Fixture_Grupos!$E$3:$E$74=$C3)*Fixture_Grupos!$H$3:$H$74*(Fixture_Grupos!$G$3:$G$74>Fixture_Grupos!$F$3:$F$74)) -> 3 | F3: =SUMPRODUCT((Fixture_Grupos!$D$3:$D$74=$C3)*Fixture_Grupos!$H$3:$H$74*(Fixture_Grupos!$F$3:$F$74=Fixture_Grupos!$G$3:$G$74))+SUMPRODUCT((Fixture_Grupos!$E$3:$E$74=$C3)*Fixture_Grupos!$H$3:$H$74*(Fixture_Grupos!$G$3:$G$74=Fixture_Grupos!$F$3:$F$74)) -> 0 | G3: =SUMPRODUCT((Fixture_Grupos!$D$3:$D$74=$C3)*Fixture_Grupos!$H$3:$H$74*(Fixture_Grupos!$F$3:$F$74<Fixture_Grupos!$G$3:$G$74))+SUMPRODUCT((Fixture_Grupos!$E$3:$E$74=$C3)*Fixture_Grupos!$H$3:$H$74*(Fixture_Grupos!$G$3:$G$74<Fixture_Grupos!$F$3:$F$74)) -> 0 | H3: =SUMPRODUCT((Fixture_Grupos!$D$3:$D$74=$C3)*Fixture_Grupos!$H$3:$H$74*Fixture_Grupos!$F$3:$F$74)+SUMPRODUCT((Fixture_Grupos!$E$3:$E$74=$C3)*Fixture_Grupos!$H$3:$H$74*Fixture_Grupos!$G$3:$G$74) -> 6 | I3: =SUMPRODUCT((Fixture_Grupos!$D$3:$D$74=$C3)*Fixture_Grupos!$H$3:$H$74*Fixture_Grupos!$G$3:$G$74)+SUMPRODUCT((Fixture_Grupos!$E$3:$E$74=$C3)*Fixture_Grupos!$H$3:$H$74*Fixture_Grupos!$F$3:$F$74) -> 0 | J3: =H3-I3 -> 6 | K3: =3*E3+F3 -> 9 | L3: =SUMPRODUCT(--(($K$3:$K$6*1000+$J$3:$J$6*10+$H$3:$H$6)>($K3*1000+$J3*10+$H3)))+1 -> 1
A4: A | B4: 2 | C4: Sudáfrica | D4: =SUMPRODUCT((Fixture_Grupos!$D$3:$D$74=$C4)*Fixture_Grupos!$H$3:$H$74)+SUMPRODUCT((Fixture_Grupos!$E$3:$E$74=$C4)*Fixture_Grupos!$H$3:$H$74) -> 3 | E4: =SUMPRODUCT((Fixture_Grupos!$D$3:$D$74=$C4)*Fixture_Grupos!$H$3:$H$74*(Fixture_Grupos!$F$3:$F$74>Fixture_Grupos!$G$3:$G$74))+SUMPRODUCT((Fixture_Grupos!$E$3:$E$74=$C4)*Fixture_Grupos!$H$3:$H$74*(Fixture_Grupos!$G$3:$G$74>Fixture_Grupos!$F$3:$F$74)) -> 1 | F4: =SUMPRODUCT((Fixture_Grupos!$D$3:$D$74=$C4)*Fixture_Grupos!$H$3:$H$74*(Fixture_Grupos!$F$3:$F$74=Fixture_Grupos!$G$3:$G$74))+SUMPRODUCT((Fixture_Grupos!$E$3:$E$74=$C4)*Fixture_Grupos!$H$3:$H$74*(Fixture_Grupos!$G$3:$G$74=Fixture_Grupos!$F$3:$F$74)) -> 1 | G4: =SUMPRODUCT((Fixture_Grupos!$D$3:$D$74=$C4)*Fixture_Grupos!$H$3:$H$74*(Fixture_Grupos!$F$3:$F$74<Fixture_Grupos!$G$3:$G$74))+SUMPRODUCT((Fixture_Grupos!$E$3:$E$74=$C4)*Fixture_Grupos!$H$3:$H$74*(Fixture_Grupos!$G$3:$G$74<Fixture_Grupos!$F$3:$F$74)) -> 1 | H4: =SUMPRODUCT((Fixture_Grupos!$D$3:$D$74=$C4)*Fixture_Grupos!$H$3:$H$74*Fixture_Grupos!$F$3:$F$74)+SUMPRODUCT((Fixture_Grupos!$E$3:$E$74=$C4)*Fixture_Grupos!$H$3:$H$74*Fixture_Grupos!$G$3:$G$74) -> 2 | I4: =SUMPRODUCT((Fixture_Grupos!$D$3:$D$74=$C4)*Fixture_Grupos!$H$3:$H$74*Fixture_Grupos!$G$3:$G$74)+SUMPRODUCT((Fixture_Grupos!$E$3:$E$74=$C4)*Fixture_Grupos!$H$3:$H$74*Fixture_Grupos!$F$3:$F$74) -> 3 | J4: =H4-I4 -> -1 | K4: =3*E4+F4 -> 4 | L4: =SUMPRODUCT(--(($K$3:$K$6*1000+$J$3:$J$6*10+$H$3:$H$6)>($K4*1000+$J4*10+$H4)))+1 -> 2
A5: A | B5: 3 | C5: Corea del Sur | D5: =SUMPRODUCT((Fixture_Grupos!$D$3:$D$74=$C5)*Fixture_Grupos!$H$3:$H$74)+SUMPRODUCT((Fixture_Grupos!$E$3:$E$74=$C5)*Fixture_Grupos!$H$3:$H$74) -> 3 | E5: =SUMPRODUCT((Fixture_Grupos!$D$3:$D$74=$C5)*Fixture_Grupos!$H$3:$H$74*(Fixture_Grupos!$F$3:$F$74>Fixture_Grupos!$G$3:$G$74))+SUMPRODUCT((Fixture_Grupos!$E$3:$E$74=$C5)*Fixture_Grupos!$H$3:$H$74*(Fixture_Grupos!$G$3:$G$74>Fixture_Grupos!$F$3:$F$74)) -> 1 | F5: =SUMPRODUCT((Fixture_Grupos!$D$3:$D$74=$C5)*Fixture_Grupos!$H$3:$H$74*(Fixture_Grupos!$F$3:$F$74=Fixture_Grupos!$G$3:$G$74))+SUMPRODUCT((Fixture_Grupos!$E$3:$E$74=$C5)*Fixture_Grupos!$H$3:$H$74*(Fixture_Grupos!$G$3:$G$74=Fixture_Grupos!$F$3:$F$74)) -> 0 | G5: =SUMPRODUCT((Fixture_Grupos!$D$3:$D$74=$C5)*Fixture_Grupos!$H$3:$H$74*(Fixture_Grupos!$F$3:$F$74<Fixture_Grupos!$G$3:$G$74))+SUMPRODUCT((Fixture_Grupos!$E$3:$E$74=$C5)*Fixture_Grupos!$H$3:$H$74*(Fixture_Grupos!$G$3:$G$74<Fixture_Grupos!$F$3:$F$74)) -> 2 | H5: =SUMPRODUCT((Fixture_Grupos!$D$3:$D$74=$C5)*Fixture_Grupos!$H$3:$H$74*Fixture_Grupos!$F$3:$F$74)+SUMPRODUCT((Fixture_Grupos!$E$3:$E$74=$C5)*Fixture_Grupos!$H$3:$H$74*Fixture_Grupos!$G$3:$G$74) -> 2 | I5: =SUMPRODUCT((Fixture_Grupos!$D$3:$D$74=$C5)*Fixture_Grupos!$H$3:$H$74*Fixture_Grupos!$G$3:$G$74)+SUMPRODUCT((Fixture_Grupos!$E$3:$E$74=$C5)*Fixture_Grupos!$H$3:$H$74*Fixture_Grupos!$F$3:$F$74) -> 3 | J5: =H5-I5 -> -1 | K5: =3*E5+F5 -> 3 | L5: =SUMPRODUCT(--(($K$3:$K$6*1000+$J$3:$J$6*10+$H$3:$H$6)>($K5*1000+$J5*10+$H5)))+1 -> 3
A6: A | B6: 4 | C6: Chequia | D6: =SUMPRODUCT((Fixture_Grupos!$D$3:$D$74=$C6)*Fixture_Grupos!$H$3:$H$74)+SUMPRODUCT((Fixture_Grupos!$E$3:$E$74=$C6)*Fixture_Grupos!$H$3:$H$74) -> 3 | E6: =SUMPRODUCT((Fixture_Grupos!$D$3:$D$74=$C6)*Fixture_Grupos!$H$3:$H$74*(Fixture_Grupos!$F$3:$F$74>Fixture_Grupos!$G$3:$G$74))+SUMPRODUCT((Fixture_Grupos!$E$3:$E$74=$C6)*Fixture_Grupos!$H$3:$H$74*(Fixture_Grupos!$G$3:$G$74>Fixture_Grupos!$F$3:$F$74)) -> 0 | F6: =SUMPRODUCT((Fixture_Grupos!$D$3:$D$74=$C6)*Fixture_Grupos!$H$3:$H$74*(Fixture_Grupos!$F$3:$F$74=Fixture_Grupos!$G$3:$G$74))+SUMPRODUCT((Fixture_Grupos!$E$3:$E$74=$C6)*Fixture_Grupos!$H$3:$H$74*(Fixture_Grupos!$G$3:$G$74=Fixture_Grupos!$F$3:$F$74)) -> 1 | G6: =SUMPRODUCT((Fixture_Grupos!$D$3:$D$74=$C6)*Fixture_Grupos!$H$3:$H$74*(Fixture_Grupos!$F$3:$F$74<Fixture_Grupos!$G$3:$G$74))+SUMPRODUCT((Fixture_Grupos!$E$3:$E$74=$C6)*Fixture_Grupos!$H$3:$H$74*(Fixture_Grupos!$G$3:$G$74<Fixture_Grupos!$F$3:$F$74)) -> 2 | H6: =SUMPRODUCT((Fixture_Grupos!$D$3:$D$74=$C6)*Fixture_Grupos!$H$3:$H$74*Fixture_Grupos!$F$3:$F$74)+SUMPRODUCT((Fixture_Grupos!$E$3:$E$74=$C6)*Fixture_Grupos!$H$3:$H$74*Fixture_Grupos!$G$3:$G$74) -> 2 | I6: =SUMPRODUCT((Fixture_Grupos!$D$3:$D$74=$C6)*Fixture_Grupos!$H$3:$H$74*Fixture_Grupos!$G$3:$G$74)+SUMPRODUCT((Fixture_Grupos!$E$3:$E$74=$C6)*Fixture_Grupos!$H$3:$H$74*Fixture_Grupos!$F$3:$F$74) -> 6 | J6: =H6-I6 -> -4 | K6: =3*E6+F6 -> 1 | L6: =SUMPRODUCT(--(($K$3:$K$6*1000+$J$3:$J$6*10+$H$3:$H$6)>($K6*1000+$J6*10+$H6)))+1 -> 4
A7: B | B7: 1 | C7: Canadá | D7: =SUMPRODUCT((Fixture_Grupos!$D$3:$D$74=$C7)*Fixture_Grupos!$H$3:$H$74)+SUMPRODUCT((Fixture_Grupos!$E$3:$E$74=$C7)*Fixture_Grupos!$H$3:$H$74) -> 3 | E7: =SUMPRODUCT((Fixture_Grupos!$D$3:$D$74=$C7)*Fixture_Grupos!$H$3:$H$74*(Fixture_Grupos!$F$3:$F$74>Fixture_Grupos!$G$3:$G$74))+SUMPRODUCT((Fixture_Grupos!$E$3:$E$74=$C7)*Fixture_Grupos!$H$3:$H$74*(Fixture_Grupos!$G$3:$G$74>Fixture_Grupos!$F$3:$F$74)) -> 1 | F7: =SUMPRODUCT((Fixture_Grupos!$D$3:$D$74=$C7)*Fixture_Grupos!$H$3:$H$74*(Fixture_Grupos!$F$3:$F$74=Fixture_Grupos!$G$3:$G$74))+SUMPRODUCT((Fixture_Grupos!$E$3:$E$74=$C7)*Fixture_Grupos!$H$3:$H$74*(Fixture_Grupos!$G$3:$G$74=Fixture_Grupos!$F$3:$F$74)) -> 1 | G7: =SUMPRODUCT((Fixture_Grupos!$D$3:$D$74=$C7)*Fixture_Grupos!$H$3:$H$74*(Fixture_Grupos!$F$3:$F$74<Fixture_Grupos!$G$3:$G$74))+SUMPRODUCT((Fixture_Grupos!$E$3:$E$74=$C7)*Fixture_Grupos!$H$3:$H$74*(Fixture_Grupos!$G$3:$G$74<Fixture_Grupos!$F$3:$F$74)) -> 1 | H7: =SUMPRODUCT((Fixture_Grupos!$D$3:$D$74=$C7)*Fixture_Grupos!$H$3:$H$74*Fixture_Grupos!$F$3:$F$74)+SUMPRODUCT((Fixture_Grupos!$E$3:$E$74=$C7)*Fixture_Grupos!$H$3:$H$74*Fixture_Grupos!$G$3:$G$74) -> 8 | I7: =SUMPRODUCT((Fixture_Grupos!$D$3:$D$74=$C7)*Fixture_Grupos!$H$3:$H$74*Fixture_Grupos!$G$3:$G$74)+SUMPRODUCT((Fixture_Grupos!$E$3:$E$74=$C7)*Fixture_Grupos!$H$3:$H$74*Fixture_Grupos!$F$3:$F$74) -> 3 | J7: =H7-I7 -> 5 | K7: =3*E7+F7 -> 4 | L7: =SUMPRODUCT(--(($K$7:$K$10*1000+$J$7:$J$10*10+$H$7:$H$10)>($K7*1000+$J7*10+$H7)))+1 -> 2
A8: B | B8: 2 | C8: Bosnia y Herzegovina | D8: =SUMPRODUCT((Fixture_Grupos!$D$3:$D$74=$C8)*Fixture_Grupos!$H$3:$H$74)+SUMPRODUCT((Fixture_Grupos!$E$3:$E$74=$C8)*Fixture_Grupos!$H$3:$H$74) -> 3 | E8: =SUMPRODUCT((Fixture_Grupos!$D$3:$D$74=$C8)*Fixture_Grupos!$H$3:$H$74*(Fixture_Grupos!$F$3:$F$74>Fixture_Grupos!$G$3:$G$74))+SUMPRODUCT((Fixture_Grupos!$E$3:$E$74=$C8)*Fixture_Grupos!$H$3:$H$74*(Fixture_Grupos!$G$3:$G$74>Fixture_Grupos!$F$3:$F$74)) -> 1 | F8: =SUMPRODUCT((Fixture_Grupos!$D$3:$D$74=$C8)*Fixture_Grupos!$H$3:$H$74*(Fixture_Grupos!$F$3:$F$74=Fixture_Grupos!$G$3:$G$74))+SUMPRODUCT((Fixture_Grupos!$E$3:$E$74=$C8)*Fixture_Grupos!$H$3:$H$74*(Fixture_Grupos!$G$3:$G$74=Fixture_Grupos!$F$3:$F$74)) -> 1 | G8: =SUMPRODUCT((Fixture_Grupos!$D$3:$D$74=$C8)*Fixture_Grupos!$H$3:$H$74*(Fixture_Grupos!$F$3:$F$74<Fixture_Grupos!$G$3:$G$74))+SUMPRODUCT((Fixture_Grupos!$E$3:$E$74=$C8)*Fixture_Grupos!$H$3:$H$74*(Fixture_Grupos!$G$3:$G$74<Fixture_Grupos!$F$3:$F$74)) -> 1 | H8: =SUMPRODUCT((Fixture_Grupos!$D$3:$D$74=$C8)*Fixture_Grupos!$H$3:$H$74*Fixture_Grupos!$F$3:$F$74)+SUMPRODUCT((Fixture_Grupos!$E$3:$E$74=$C8)*Fixture_Grupos!$H$3:$H$74*Fixture_Grupos!$G$3:$G$74) -> 5 | I8: =SUMPRODUCT((Fixture_Grupos!$D$3:$D$74=$C8)*Fixture_Grupos!$H$3:$H$74*Fixture_Grupos!$G$3:$G$74)+SUMPRODUCT((Fixture_Grupos!$E$3:$E$74=$C8)*Fixture_Grupos!$H$3:$H$74*Fixture_Grupos!$F$3:$F$74) -> 6 | J8: =H8-I8 -> -1 | K8: =3*E8+F8 -> 4 | L8: =SUMPRODUCT(--(($K$7:$K$10*1000+$J$7:$J$10*10+$H$7:$H$10)>($K8*1000+$J8*10+$H8)))+1 -> 3
A9: B | B9: 3 | C9: Catar | D9: =SUMPRODUCT((Fixture_Grupos!$D$3:$D$74=$C9)*Fixture_Grupos!$H$3:$H$74)+SUMPRODUCT((Fixture_Grupos!$E$3:$E$74=$C9)*Fixture_Grupos!$H$3:$H$74) -> 3 | E9: =SUMPRODUCT((Fixture_Grupos!$D$3:$D$74=$C9)*Fixture_Grupos!$H$3:$H$74*(Fixture_Grupos!$F$3:$F$74>Fixture_Grupos!$G$3:$G$74))+SUMPRODUCT((Fixture_Grupos!$E$3:$E$74=$C9)*Fixture_Grupos!$H$3:$H$74*(Fixture_Grupos!$G$3:$G$74>Fixture_Grupos!$F$3:$F$74)) -> 0 | F9: =SUMPRODUCT((Fixture_Grupos!$D$3:$D$74=$C9)*Fixture_Grupos!$H$3:$H$74*(Fixture_Grupos!$F$3:$F$74=Fixture_Grupos!$G$3:$G$74))+SUMPRODUCT((Fixture_Grupos!$E$3:$E$74=$C9)*Fixture_Grupos!$H$3:$H$74*(Fixture_Grupos!$G$3:$G$74=Fixture_Grupos!$F$3:$F$74)) -> 1 | G9: =SUMPRODUCT((Fixture_Grupos!$D$3:$D$74=$C9)*Fixture_Grupos!$H$3:$H$74*(Fixture_Grupos!$F$3:$F$74<Fixture_Grupos!$G$3:$G$74))+SUMPRODUCT((Fixture_Grupos!$E$3:$E$74=$C9)*Fixture_Grupos!$H$3:$H$74*(Fixture_Grupos!$G$3:$G$74<Fixture_Grupos!$F$3:$F$74)) -> 2 | H9: =SUMPRODUCT((Fixture_Grupos!$D$3:$D$74=$C9)*Fixture_Grupos!$H$3:$H$74*Fixture_Grupos!$F$3:$F$74)+SUMPRODUCT((Fixture_Grupos!$E$3:$E$74=$C9)*Fixture_Grupos!$H$3:$H$74*Fixture_Grupos!$G$3:$G$74) -> 2 | I9: =SUMPRODUCT((Fixture_Grupos!$D$3:$D$74=$C9)*Fixture_Grupos!$H$3:$H$74*Fixture_Grupos!$G$3:$G$74)+SUMPRODUCT((Fixture_Grupos!$E$3:$E$74=$C9)*Fixture_Grupos!$H$3:$H$74*Fixture_Grupos!$F$3:$F$74) -> 10 | J9: =H9-I9 -> -8 | K9: =3*E9+F9 -> 1 | L9: =SUMPRODUCT(--(($K$7:$K$10*1000+$J$7:$J$10*10+$H$7:$H$10)>($K9*1000+$J9*10+$H9)))+1 -> 4
A10: B | B10: 4 | C10: Suiza | D10: =SUMPRODUCT((Fixture_Grupos!$D$3:$D$74=$C10)*Fixture_Grupos!$H$3:$H$74)+SUMPRODUCT((Fixture_Grupos!$E$3:$E$74=$C10)*Fixture_Grupos!$H$3:$H$74) -> 3 | E10: =SUMPRODUCT((Fixture_Grupos!$D$3:$D$74=$C10)*Fixture_Grupos!$H$3:$H$74*(Fixture_Grupos!$F$3:$F$74>Fixture_Grupos!$G$3:$G$74))+SUMPRODUCT((Fixture_Grupos!$E$3:$E$74=$C10)*Fixture_Grupos!$H$3:$H$74*(Fixture_Grupos!$G$3:$G$74>Fixture_Grupos!$F$3:$F$74)) -> 2 | F10: =SUMPRODUCT((Fixture_Grupos!$D$3:$D$74=$C10)*Fixture_Grupos!$H$3:$H$74*(Fixture_Grupos!$F$3:$F$74=Fixture_Grupos!$G$3:$G$74))+SUMPRODUCT((Fixture_Grupos!$E$3:$E$74=$C10)*Fixture_Grupos!$H$3:$H$74*(Fixture_Grupos!$G$3:$G$74=Fixture_Grupos!$F$3:$F$74)) -> 1 | G10: =SUMPRODUCT((Fixture_Grupos!$D$3:$D$74=$C10)*Fixture_Grupos!$H$3:$H$74*(Fixture_Grupos!$F$3:$F$74<Fixture_Grupos!$G$3:$G$74))+SUMPRODUCT((Fixture_Grupos!$E$3:$E$74=$C10)*Fixture_Grupos!$H$3:$H$74*(Fixture_Grupos!$G$3:$G$74<Fixture_Grupos!$F$3:$F$74)) -> 0 | H10: =SUMPRODUCT((Fixture_Grupos!$D$3:$D$74=$C10)*Fixture_Grupos!$H$3:$H$74*Fixture_Grupos!$F$3:$F$74)+SUMPRODUCT((Fixture_Grupos!$E$3:$E$74=$C10)*Fixture_Grupos!$H$3:$H$74*Fixture_Grupos!$G$3:$G$74) -> 7 | I10: =SUMPRODUCT((Fixture_Grupos!$D$3:$D$74=$C10)*Fixture_Grupos!$H$3:$H$74*Fixture_Grupos!$G$3:$G$74)+SUMPRODUCT((Fixture_Grupos!$E$3:$E$74=$C10)*Fixture_Grupos!$H$3:$H$74*Fixture_Grupos!$F$3:$F$74) -> 3 | J10: =H10-I10 -> 4 | K10: =3*E10+F10 -> 7 | L10: =SUMPRODUCT(--(($K$7:$K$10*1000+$J$7:$J$10*10+$H$7:$H$10)>($K10*1000+$J10*10+$H10)))+1 -> 1
A11: C | B11: 1 | C11: Brasil | D11: =SUMPRODUCT((Fixture_Grupos!$D$3:$D$74=$C11)*Fixture_Grupos!$H$3:$H$74)+SUMPRODUCT((Fixture_Grupos!$E$3:$E$74=$C11)*Fixture_Grupos!$H$3:$H$74) -> 3 | E11: =SUMPRODUCT((Fixture_Grupos!$D$3:$D$74=$C11)*Fixture_Grupos!$H$3:$H$74*(Fixture_Grupos!$F$3:$F$74>Fixture_Grupos!$G$3:$G$74))+SUMPRODUCT((Fixture_Grupos!$E$3:$E$74=$C11)*Fixture_Grupos!$H$3:$H$74*(Fixture_Grupos!$G$3:$G$74>Fixture_Grupos!$F$3:$F$74)) -> 2 | F11: =SUMPRODUCT((Fixture_Grupos!$D$3:$D$74=$C11)*Fixture_Grupos!$H$3:$H$74*(Fixture_Grupos!$F$3:$F$74=Fixture_Grupos!$G$3:$G$74))+SUMPRODUCT((Fixture_Grupos!$E$3:$E$74=$C11)*Fixture_Grupos!$H$3:$H$74*(Fixture_Grupos!$G$3:$G$74=Fixture_Grupos!$F$3:$F$74)) -> 1 | G11: =SUMPRODUCT((Fixture_Grupos!$D$3:$D$74=$C11)*Fixture_Grupos!$H$3:$H$74*(Fixture_Grupos!$F$3:$F$74<Fixture_Grupos!$G$3:$G$74))+SUMPRODUCT((Fixture_Grupos!$E$3:$E$74=$C11)*Fixture_Grupos!$H$3:$H$74*(Fixture_Grupos!$G$3:$G$74<Fixture_Grupos!$F$3:$F$74)) -> 0 | H11: =SUMPRODUCT((Fixture_Grupos!$D$3:$D$74=$C11)*Fixture_Grupos!$H$3:$H$74*Fixture_Grupos!$F$3:$F$74)+SUMPRODUCT((Fixture_Grupos!$E$3:$E$74=$C11)*Fixture_Grupos!$H$3:$H$74*Fixture_Grupos!$G$3:$G$74) -> 7 | I11: =SUMPRODUCT((Fixture_Grupos!$D$3:$D$74=$C11)*Fixture_Grupos!$H$3:$H$74*Fixture_Grupos!$G$3:$G$74)+SUMPRODUCT((Fixture_Grupos!$E$3:$E$74=$C11)*Fixture_Grupos!$H$3:$H$74*Fixture_Grupos!$F$3:$F$74) -> 1 | J11: =H11-I11 -> 6 | K11: =3*E11+F11 -> 7 | L11: =SUMPRODUCT(--(($K$11:$K$14*1000+$J$11:$J$14*10+$H$11:$H$14)>($K11*1000+$J11*10+$H11)))+1 -> 1
A12: C | B12: 2 | C12: Marruecos | D12: =SUMPRODUCT((Fixture_Grupos!$D$3:$D$74=$C12)*Fixture_Grupos!$H$3:$H$74)+SUMPRODUCT((Fixture_Grupos!$E$3:$E$74=$C12)*Fixture_Grupos!$H$3:$H$74) -> 3 | E12: =SUMPRODUCT((Fixture_Grupos!$D$3:$D$74=$C12)*Fixture_Grupos!$H$3:$H$74*(Fixture_Grupos!$F$3:$F$74>Fixture_Grupos!$G$3:$G$74))+SUMPRODUCT((Fixture_Grupos!$E$3:$E$74=$C12)*Fixture_Grupos!$H$3:$H$74*(Fixture_Grupos!$G$3:$G$74>Fixture_Grupos!$F$3:$F$74)) -> 2 | F12: =SUMPRODUCT((Fixture_Grupos!$D$3:$D$74=$C12)*Fixture_Grupos!$H$3:$H$74*(Fixture_Grupos!$F$3:$F$74=Fixture_Grupos!$G$3:$G$74))+SUMPRODUCT((Fixture_Grupos!$E$3:$E$74=$C12)*Fixture_Grupos!$H$3:$H$74*(Fixture_Grupos!$G$3:$G$74=Fixture_Grupos!$F$3:$F$74)) -> 1 | G12: =SUMPRODUCT((Fixture_Grupos!$D$3:$D$74=$C12)*Fixture_Grupos!$H$3:$H$74*(Fixture_Grupos!$F$3:$F$74<Fixture_Grupos!$G$3:$G$74))+SUMPRODUCT((Fixture_Grupos!$E$3:$E$74=$C12)*Fixture_Grupos!$H$3:$H$74*(Fixture_Grupos!$G$3:$G$74<Fixture_Grupos!$F$3:$F$74)) -> 0 | H12: =SUMPRODUCT((Fixture_Grupos!$D$3:$D$74=$C12)*Fixture_Grupos!$H$3:$H$74*Fixture_Grupos!$F$3:$F$74)+SUMPRODUCT((Fixture_Grupos!$E$3:$E$74=$C12)*Fixture_Grupos!$H$3:$H$74*Fixture_Grupos!$G$3:$G$74) -> 6 | I12: =SUMPRODUCT((Fixture_Grupos!$D$3:$D$74=$C12)*Fixture_Grupos!$H$3:$H$74*Fixture_Grupos!$G$3:$G$74)+SUMPRODUCT((Fixture_Grupos!$E$3:$E$74=$C12)*Fixture_Grupos!$H$3:$H$74*Fixture_Grupos!$F$3:$F$74) -> 3 | J12: =H12-I12 -> 3 | K12: =3*E12+F12 -> 7 | L12: =SUMPRODUCT(--(($K$11:$K$14*1000+$J$11:$J$14*10+$H$11:$H$14)>($K12*1000+$J12*10+$H12)))+1 -> 2
A13: C | B13: 3 | C13: Haití | D13: =SUMPRODUCT((Fixture_Grupos!$D$3:$D$74=$C13)*Fixture_Grupos!$H$3:$H$74)+SUMPRODUCT((Fixture_Grupos!$E$3:$E$74=$C13)*Fixture_Grupos!$H$3:$H$74) -> 3 | E13: =SUMPRODUCT((Fixture_Grupos!$D$3:$D$74=$C13)*Fixture_Grupos!$H$3:$H$74*(Fixture_Grupos!$F$3:$F$74>Fixture_Grupos!$G$3:$G$74))+SUMPRODUCT((Fixture_Grupos!$E$3:$E$74=$C13)*Fixture_Grupos!$H$3:$H$74*(Fixture_Grupos!$G$3:$G$74>Fixture_Grupos!$F$3:$F$74)) -> 0 | F13: =SUMPRODUCT((Fixture_Grupos!$D$3:$D$74=$C13)*Fixture_Grupos!$H$3:$H$74*(Fixture_Grupos!$F$3:$F$74=Fixture_Grupos!$G$3:$G$74))+SUMPRODUCT((Fixture_Grupos!$E$3:$E$74=$C13)*Fixture_Grupos!$H$3:$H$74*(Fixture_Grupos!$G$3:$G$74=Fixture_Grupos!$F$3:$F$74)) -> 0 | G13: =SUMPRODUCT((Fixture_Grupos!$D$3:$D$74=$C13)*Fixture_Grupos!$H$3:$H$74*(Fixture_Grupos!$F$3:$F$74<Fixture_Grupos!$G$3:$G$74))+SUMPRODUCT((Fixture_Grupos!$E$3:$E$74=$C13)*Fixture_Grupos!$H$3:$H$74*(Fixture_Grupos!$G$3:$G$74<Fixture_Grupos!$F$3:$F$74)) -> 3 | H13: =SUMPRODUCT((Fixture_Grupos!$D$3:$D$74=$C13)*Fixture_Grupos!$H$3:$H$74*Fixture_Grupos!$F$3:$F$74)+SUMPRODUCT((Fixture_Grupos!$E$3:$E$74=$C13)*Fixture_Grupos!$H$3:$H$74*Fixture_Grupos!$G$3:$G$74) -> 2 | I13: =SUMPRODUCT((Fixture_Grupos!$D$3:$D$74=$C13)*Fixture_Grupos!$H$3:$H$74*Fixture_Grupos!$G$3:$G$74)+SUMPRODUCT((Fixture_Grupos!$E$3:$E$74=$C13)*Fixture_Grupos!$H$3:$H$74*Fixture_Grupos!$F$3:$F$74) -> 8 | J13: =H13-I13 -> -6 | K13: =3*E13+F13 -> 0 | L13: =SUMPRODUCT(--(($K$11:$K$14*1000+$J$11:$J$14*10+$H$11:$H$14)>($K13*1000+$J13*10+$H13)))+1 -> 4
A14: C | B14: 4 | C14: Escocia | D14: =SUMPRODUCT((Fixture_Grupos!$D$3:$D$74=$C14)*Fixture_Grupos!$H$3:$H$74)+SUMPRODUCT((Fixture_Grupos!$E$3:$E$74=$C14)*Fixture_Grupos!$H$3:$H$74) -> 3 | E14: =SUMPRODUCT((Fixture_Grupos!$D$3:$D$74=$C14)*Fixture_Grupos!$H$3:$H$74*(Fixture_Grupos!$F$3:$F$74>Fixture_Grupos!$G$3:$G$74))+SUMPRODUCT((Fixture_Grupos!$E$3:$E$74=$C14)*Fixture_Grupos!$H$3:$H$74*(Fixture_Grupos!$G$3:$G$74>Fixture_Grupos!$F$3:$F$74)) -> 1 | F14: =SUMPRODUCT((Fixture_Grupos!$D$3:$D$74=$C14)*Fixture_Grupos!$H$3:$H$74*(Fixture_Grupos!$F$3:$F$74=Fixture_Grupos!$G$3:$G$74))+SUMPRODUCT((Fixture_Grupos!$E$3:$E$74=$C14)*Fixture_Grupos!$H$3:$H$74*(Fixture_Grupos!$G$3:$G$74=Fixture_Grupos!$F$3:$F$74)) -> 0 | G14: =SUMPRODUCT((Fixture_Grupos!$D$3:$D$74=$C14)*Fixture_Grupos!$H$3:$H$74*(Fixture_Grupos!$F$3:$F$74<Fixture_Grupos!$G$3:$G$74))+SUMPRODUCT((Fixture_Grupos!$E$3:$E$74=$C14)*Fixture_Grupos!$H$3:$H$74*(Fixture_Grupos!$G$3:$G$74<Fixture_Grupos!$F$3:$F$74)) -> 2 | H14: =SUMPRODUCT((Fixture_Grupos!$D$3:$D$74=$C14)*Fixture_Grupos!$H$3:$H$74*Fixture_Grupos!$F$3:$F$74)+SUMPRODUCT((Fixture_Grupos!$E$3:$E$74=$C14)*Fixture_Grupos!$H$3:$H$74*Fixture_Grupos!$G$3:$G$74) -> 1 | I14: =SUMPRODUCT((Fixture_Grupos!$D$3:$D$74=$C14)*Fixture_Grupos!$H$3:$H$74*Fixture_Grupos!$G$3:$G$74)+SUMPRODUCT((Fixture_Grupos!$E$3:$E$74=$C14)*Fixture_Grupos!$H$3:$H$74*Fixture_Grupos!$F$3:$F$74) -> 4 | J14: =H14-I14 -> -3 | K14: =3*E14+F14 -> 3 | L14: =SUMPRODUCT(--(($K$11:$K$14*1000+$J$11:$J$14*10+$H$11:$H$14)>($K14*1000+$J14*10+$H14)))+1 -> 3
A15: D | B15: 1 | C15: Estados Unidos | D15: =SUMPRODUCT((Fixture_Grupos!$D$3:$D$74=$C15)*Fixture_Grupos!$H$3:$H$74)+SUMPRODUCT((Fixture_Grupos!$E$3:$E$74=$C15)*Fixture_Grupos!$H$3:$H$74) -> 3 | E15: =SUMPRODUCT((Fixture_Grupos!$D$3:$D$74=$C15)*Fixture_Grupos!$H$3:$H$74*(Fixture_Grupos!$F$3:$F$74>Fixture_Grupos!$G$3:$G$74))+SUMPRODUCT((Fixture_Grupos!$E$3:$E$74=$C15)*Fixture_Grupos!$H$3:$H$74*(Fixture_Grupos!$G$3:$G$74>Fixture_Grupos!$F$3:$F$74)) -> 2 | F15: =SUMPRODUCT((Fixture_Grupos!$D$3:$D$74=$C15)*Fixture_Grupos!$H$3:$H$74*(Fixture_Grupos!$F$3:$F$74=Fixture_Grupos!$G$3:$G$74))+SUMPRODUCT((Fixture_Grupos!$E$3:$E$74=$C15)*Fixture_Grupos!$H$3:$H$74*(Fixture_Grupos!$G$3:$G$74=Fixture_Grupos!$F$3:$F$74)) -> 0 | G15: =SUMPRODUCT((Fixture_Grupos!$D$3:$D$74=$C15)*Fixture_Grupos!$H$3:$H$74*(Fixture_Grupos!$F$3:$F$74<Fixture_Grupos!$G$3:$G$74))+SUMPRODUCT((Fixture_Grupos!$E$3:$E$74=$C15)*Fixture_Grupos!$H$3:$H$74*(Fixture_Grupos!$G$3:$G$74<Fixture_Grupos!$F$3:$F$74)) -> 1 | H15: =SUMPRODUCT((Fixture_Grupos!$D$3:$D$74=$C15)*Fixture_Grupos!$H$3:$H$74*Fixture_Grupos!$F$3:$F$74)+SUMPRODUCT((Fixture_Grupos!$E$3:$E$74=$C15)*Fixture_Grupos!$H$3:$H$74*Fixture_Grupos!$G$3:$G$74) -> 8 | I15: =SUMPRODUCT((Fixture_Grupos!$D$3:$D$74=$C15)*Fixture_Grupos!$H$3:$H$74*Fixture_Grupos!$G$3:$G$74)+SUMPRODUCT((Fixture_Grupos!$E$3:$E$74=$C15)*Fixture_Grupos!$H$3:$H$74*Fixture_Grupos!$F$3:$F$74) -> 4 | J15: =H15-I15 -> 4 | K15: =3*E15+F15 -> 6 | L15: =SUMPRODUCT(--(($K$15:$K$18*1000+$J$15:$J$18*10+$H$15:$H$18)>($K15*1000+$J15*10+$H15)))+1 -> 1
A16: D | B16: 2 | C16: Paraguay | D16: =SUMPRODUCT((Fixture_Grupos!$D$3:$D$74=$C16)*Fixture_Grupos!$H$3:$H$74)+SUMPRODUCT((Fixture_Grupos!$E$3:$E$74=$C16)*Fixture_Grupos!$H$3:$H$74) -> 3 | E16: =SUMPRODUCT((Fixture_Grupos!$D$3:$D$74=$C16)*Fixture_Grupos!$H$3:$H$74*(Fixture_Grupos!$F$3:$F$74>Fixture_Grupos!$G$3:$G$74))+SUMPRODUCT((Fixture_Grupos!$E$3:$E$74=$C16)*Fixture_Grupos!$H$3:$H$74*(Fixture_Grupos!$G$3:$G$74>Fixture_Grupos!$F$3:$F$74)) -> 1 | F16: =SUMPRODUCT((Fixture_Grupos!$D$3:$D$74=$C16)*Fixture_Grupos!$H$3:$H$74*(Fixture_Grupos!$F$3:$F$74=Fixture_Grupos!$G$3:$G$74))+SUMPRODUCT((Fixture_Grupos!$E$3:$E$74=$C16)*Fixture_Grupos!$H$3:$H$74*(Fixture_Grupos!$G$3:$G$74=Fixture_Grupos!$F$3:$F$74)) -> 1 | G16: =SUMPRODUCT((Fixture_Grupos!$D$3:$D$74=$C16)*Fixture_Grupos!$H$3:$H$74*(Fixture_Grupos!$F$3:$F$74<Fixture_Grupos!$G$3:$G$74))+SUMPRODUCT((Fixture_Grupos!$E$3:$E$74=$C16)*Fixture_Grupos!$H$3:$H$74*(Fixture_Grupos!$G$3:$G$74<Fixture_Grupos!$F$3:$F$74)) -> 1 | H16: =SUMPRODUCT((Fixture_Grupos!$D$3:$D$74=$C16)*Fixture_Grupos!$H$3:$H$74*Fixture_Grupos!$F$3:$F$74)+SUMPRODUCT((Fixture_Grupos!$E$3:$E$74=$C16)*Fixture_Grupos!$H$3:$H$74*Fixture_Grupos!$G$3:$G$74) -> 2 | I16: =SUMPRODUCT((Fixture_Grupos!$D$3:$D$74=$C16)*Fixture_Grupos!$H$3:$H$74*Fixture_Grupos!$G$3:$G$74)+SUMPRODUCT((Fixture_Grupos!$E$3:$E$74=$C16)*Fixture_Grupos!$H$3:$H$74*Fixture_Grupos!$F$3:$F$74) -> 4 | J16: =H16-I16 -> -2 | K16: =3*E16+F16 -> 4 | L16: =SUMPRODUCT(--(($K$15:$K$18*1000+$J$15:$J$18*10+$H$15:$H$18)>($K16*1000+$J16*10+$H16)))+1 -> 3
A17: D | B17: 3 | C17: Australia | D17: =SUMPRODUCT((Fixture_Grupos!$D$3:$D$74=$C17)*Fixture_Grupos!$H$3:$H$74)+SUMPRODUCT((Fixture_Grupos!$E$3:$E$74=$C17)*Fixture_Grupos!$H$3:$H$74) -> 3 | E17: =SUMPRODUCT((Fixture_Grupos!$D$3:$D$74=$C17)*Fixture_Grupos!$H$3:$H$74*(Fixture_Grupos!$F$3:$F$74>Fixture_Grupos!$G$3:$G$74))+SUMPRODUCT((Fixture_Grupos!$E$3:$E$74=$C17)*Fixture_Grupos!$H$3:$H$74*(Fixture_Grupos!$G$3:$G$74>Fixture_Grupos!$F$3:$F$74)) -> 1 | F17: =SUMPRODUCT((Fixture_Grupos!$D$3:$D$74=$C17)*Fixture_Grupos!$H$3:$H$74*(Fixture_Grupos!$F$3:$F$74=Fixture_Grupos!$G$3:$G$74))+SUMPRODUCT((Fixture_Grupos!$E$3:$E$74=$C17)*Fixture_Grupos!$H$3:$H$74*(Fixture_Grupos!$G$3:$G$74=Fixture_Grupos!$F$3:$F$74)) -> 1 | G17: =SUMPRODUCT((Fixture_Grupos!$D$3:$D$74=$C17)*Fixture_Grupos!$H$3:$H$74*(Fixture_Grupos!$F$3:$F$74<Fixture_Grupos!$G$3:$G$74))+SUMPRODUCT((Fixture_Grupos!$E$3:$E$74=$C17)*Fixture_Grupos!$H$3:$H$74*(Fixture_Grupos!$G$3:$G$74<Fixture_Grupos!$F$3:$F$74)) -> 1 | H17: =SUMPRODUCT((Fixture_Grupos!$D$3:$D$74=$C17)*Fixture_Grupos!$H$3:$H$74*Fixture_Grupos!$F$3:$F$74)+SUMPRODUCT((Fixture_Grupos!$E$3:$E$74=$C17)*Fixture_Grupos!$H$3:$H$74*Fixture_Grupos!$G$3:$G$74) -> 2 | I17: =SUMPRODUCT((Fixture_Grupos!$D$3:$D$74=$C17)*Fixture_Grupos!$H$3:$H$74*Fixture_Grupos!$G$3:$G$74)+SUMPRODUCT((Fixture_Grupos!$E$3:$E$74=$C17)*Fixture_Grupos!$H$3:$H$74*Fixture_Grupos!$F$3:$F$74) -> 2 | J17: =H17-I17 -> 0 | K17: =3*E17+F17 -> 4 | L17: =SUMPRODUCT(--(($K$15:$K$18*1000+$J$15:$J$18*10+$H$15:$H$18)>($K17*1000+$J17*10+$H17)))+1 -> 2
A18: D | B18: 4 | C18: Turquía | D18: =SUMPRODUCT((Fixture_Grupos!$D$3:$D$74=$C18)*Fixture_Grupos!$H$3:$H$74)+SUMPRODUCT((Fixture_Grupos!$E$3:$E$74=$C18)*Fixture_Grupos!$H$3:$H$74) -> 3 | E18: =SUMPRODUCT((Fixture_Grupos!$D$3:$D$74=$C18)*Fixture_Grupos!$H$3:$H$74*(Fixture_Grupos!$F$3:$F$74>Fixture_Grupos!$G$3:$G$74))+SUMPRODUCT((Fixture_Grupos!$E$3:$E$74=$C18)*Fixture_Grupos!$H$3:$H$74*(Fixture_Grupos!$G$3:$G$74>Fixture_Grupos!$F$3:$F$74)) -> 1 | F18: =SUMPRODUCT((Fixture_Grupos!$D$3:$D$74=$C18)*Fixture_Grupos!$H$3:$H$74*(Fixture_Grupos!$F$3:$F$74=Fixture_Grupos!$G$3:$G$74))+SUMPRODUCT((Fixture_Grupos!$E$3:$E$74=$C18)*Fixture_Grupos!$H$3:$H$74*(Fixture_Grupos!$G$3:$G$74=Fixture_Grupos!$F$3:$F$74)) -> 0 | G18: =SUMPRODUCT((Fixture_Grupos!$D$3:$D$74=$C18)*Fixture_Grupos!$H$3:$H$74*(Fixture_Grupos!$F$3:$F$74<Fixture_Grupos!$G$3:$G$74))+SUMPRODUCT((Fixture_Grupos!$E$3:$E$74=$C18)*Fixture_Grupos!$H$3:$H$74*(Fixture_Grupos!$G$3:$G$74<Fixture_Grupos!$F$3:$F$74)) -> 2 | H18: =SUMPRODUCT((Fixture_Grupos!$D$3:$D$74=$C18)*Fixture_Grupos!$H$3:$H$74*Fixture_Grupos!$F$3:$F$74)+SUMPRODUCT((Fixture_Grupos!$E$3:$E$74=$C18)*Fixture_Grupos!$H$3:$H$74*Fixture_Grupos!$G$3:$G$74) -> 3 | I18: =SUMPRODUCT((Fixture_Grupos!$D$3:$D$74=$C18)*Fixture_Grupos!$H$3:$H$74*Fixture_Grupos!$G$3:$G$74)+SUMPRODUCT((Fixture_Grupos!$E$3:$E$74=$C18)*Fixture_Grupos!$H$3:$H$74*Fixture_Grupos!$F$3:$F$74) -> 5 | J18: =H18-I18 -> -2 | K18: =3*E18+F18 -> 3 | L18: =SUMPRODUCT(--(($K$15:$K$18*1000+$J$15:$J$18*10+$H$15:$H$18)>($K18*1000+$J18*10+$H18)))+1 -> 4
A19: E | B19: 1 | C19: Alemania | D19: =SUMPRODUCT((Fixture_Grupos!$D$3:$D$74=$C19)*Fixture_Grupos!$H$3:$H$74)+SUMPRODUCT((Fixture_Grupos!$E$3:$E$74=$C19)*Fixture_Grupos!$H$3:$H$74) -> 3 | E19: =SUMPRODUCT((Fixture_Grupos!$D$3:$D$74=$C19)*Fixture_Grupos!$H$3:$H$74*(Fixture_Grupos!$F$3:$F$74>Fixture_Grupos!$G$3:$G$74))+SUMPRODUCT((Fixture_Grupos!$E$3:$E$74=$C19)*Fixture_Grupos!$H$3:$H$74*(Fixture_Grupos!$G$3:$G$74>Fixture_Grupos!$F$3:$F$74)) -> 2 | F19: =SUMPRODUCT((Fixture_Grupos!$D$3:$D$74=$C19)*Fixture_Grupos!$H$3:$H$74*(Fixture_Grupos!$F$3:$F$74=Fixture_Grupos!$G$3:$G$74))+SUMPRODUCT((Fixture_Grupos!$E$3:$E$74=$C19)*Fixture_Grupos!$H$3:$H$74*(Fixture_Grupos!$G$3:$G$74=Fixture_Grupos!$F$3:$F$74)) -> 0 | G19: =SUMPRODUCT((Fixture_Grupos!$D$3:$D$74=$C19)*Fixture_Grupos!$H$3:$H$74*(Fixture_Grupos!$F$3:$F$74<Fixture_Grupos!$G$3:$G$74))+SUMPRODUCT((Fixture_Grupos!$E$3:$E$74=$C19)*Fixture_Grupos!$H$3:$H$74*(Fixture_Grupos!$G$3:$G$74<Fixture_Grupos!$F$3:$F$74)) -> 1 | H19: =SUMPRODUCT((Fixture_Grupos!$D$3:$D$74=$C19)*Fixture_Grupos!$H$3:$H$74*Fixture_Grupos!$F$3:$F$74)+SUMPRODUCT((Fixture_Grupos!$E$3:$E$74=$C19)*Fixture_Grupos!$H$3:$H$74*Fixture_Grupos!$G$3:$G$74) -> 10 | I19: =SUMPRODUCT((Fixture_Grupos!$D$3:$D$74=$C19)*Fixture_Grupos!$H$3:$H$74*Fixture_Grupos!$G$3:$G$74)+SUMPRODUCT((Fixture_Grupos!$E$3:$E$74=$C19)*Fixture_Grupos!$H$3:$H$74*Fixture_Grupos!$F$3:$F$74) -> 4 | J19: =H19-I19 -> 6 | K19: =3*E19+F19 -> 6 | L19: =SUMPRODUCT(--(($K$19:$K$22*1000+$J$19:$J$22*10+$H$19:$H$22)>($K19*1000+$J19*10+$H19)))+1 -> 1
A20: E | B20: 2 | C20: Curazao | D20: =SUMPRODUCT((Fixture_Grupos!$D$3:$D$74=$C20)*Fixture_Grupos!$H$3:$H$74)+SUMPRODUCT((Fixture_Grupos!$E$3:$E$74=$C20)*Fixture_Grupos!$H$3:$H$74) -> 3 | E20: =SUMPRODUCT((Fixture_Grupos!$D$3:$D$74=$C20)*Fixture_Grupos!$H$3:$H$74*(Fixture_Grupos!$F$3:$F$74>Fixture_Grupos!$G$3:$G$74))+SUMPRODUCT((Fixture_Grupos!$E$3:$E$74=$C20)*Fixture_Grupos!$H$3:$H$74*(Fixture_Grupos!$G$3:$G$74>Fixture_Grupos!$F$3:$F$74)) -> 0 | F20: =SUMPRODUCT((Fixture_Grupos!$D$3:$D$74=$C20)*Fixture_Grupos!$H$3:$H$74*(Fixture_Grupos!$F$3:$F$74=Fixture_Grupos!$G$3:$G$74))+SUMPRODUCT((Fixture_Grupos!$E$3:$E$74=$C20)*Fixture_Grupos!$H$3:$H$74*(Fixture_Grupos!$G$3:$G$74=Fixture_Grupos!$F$3:$F$74)) -> 1 | G20: =SUMPRODUCT((Fixture_Grupos!$D$3:$D$74=$C20)*Fixture_Grupos!$H$3:$H$74*(Fixture_Grupos!$F$3:$F$74<Fixture_Grupos!$G$3:$G$74))+SUMPRODUCT((Fixture_Grupos!$E$3:$E$74=$C20)*Fixture_Grupos!$H$3:$H$74*(Fixture_Grupos!$G$3:$G$74<Fixture_Grupos!$F$3:$F$74)) -> 2 | H20: =SUMPRODUCT((Fixture_Grupos!$D$3:$D$74=$C20)*Fixture_Grupos!$H$3:$H$74*Fixture_Grupos!$F$3:$F$74)+SUMPRODUCT((Fixture_Grupos!$E$3:$E$74=$C20)*Fixture_Grupos!$H$3:$H$74*Fixture_Grupos!$G$3:$G$74) -> 1 | I20: =SUMPRODUCT((Fixture_Grupos!$D$3:$D$74=$C20)*Fixture_Grupos!$H$3:$H$74*Fixture_Grupos!$G$3:$G$74)+SUMPRODUCT((Fixture_Grupos!$E$3:$E$74=$C20)*Fixture_Grupos!$H$3:$H$74*Fixture_Grupos!$F$3:$F$74) -> 9 | J20: =H20-I20 -> -8 | K20: =3*E20+F20 -> 1 | L20: =SUMPRODUCT(--(($K$19:$K$22*1000+$J$19:$J$22*10+$H$19:$H$22)>($K20*1000+$J20*10+$H20)))+1 -> 4
A21: E | B21: 3 | C21: Costa de Marfil | D21: =SUMPRODUCT((Fixture_Grupos!$D$3:$D$74=$C21)*Fixture_Grupos!$H$3:$H$74)+SUMPRODUCT((Fixture_Grupos!$E$3:$E$74=$C21)*Fixture_Grupos!$H$3:$H$74) -> 3 | E21: =SUMPRODUCT((Fixture_Grupos!$D$3:$D$74=$C21)*Fixture_Grupos!$H$3:$H$74*(Fixture_Grupos!$F$3:$F$74>Fixture_Grupos!$G$3:$G$74))+SUMPRODUCT((Fixture_Grupos!$E$3:$E$74=$C21)*Fixture_Grupos!$H$3:$H$74*(Fixture_Grupos!$G$3:$G$74>Fixture_Grupos!$F$3:$F$74)) -> 2 | F21: =SUMPRODUCT((Fixture_Grupos!$D$3:$D$74=$C21)*Fixture_Grupos!$H$3:$H$74*(Fixture_Grupos!$F$3:$F$74=Fixture_Grupos!$G$3:$G$74))+SUMPRODUCT((Fixture_Grupos!$E$3:$E$74=$C21)*Fixture_Grupos!$H$3:$H$74*(Fixture_Grupos!$G$3:$G$74=Fixture_Grupos!$F$3:$F$74)) -> 0 | G21: =SUMPRODUCT((Fixture_Grupos!$D$3:$D$74=$C21)*Fixture_Grupos!$H$3:$H$74*(Fixture_Grupos!$F$3:$F$74<Fixture_Grupos!$G$3:$G$74))+SUMPRODUCT((Fixture_Grupos!$E$3:$E$74=$C21)*Fixture_Grupos!$H$3:$H$74*(Fixture_Grupos!$G$3:$G$74<Fixture_Grupos!$F$3:$F$74)) -> 1 | H21: =SUMPRODUCT((Fixture_Grupos!$D$3:$D$74=$C21)*Fixture_Grupos!$H$3:$H$74*Fixture_Grupos!$F$3:$F$74)+SUMPRODUCT((Fixture_Grupos!$E$3:$E$74=$C21)*Fixture_Grupos!$H$3:$H$74*Fixture_Grupos!$G$3:$G$74) -> 4 | I21: =SUMPRODUCT((Fixture_Grupos!$D$3:$D$74=$C21)*Fixture_Grupos!$H$3:$H$74*Fixture_Grupos!$G$3:$G$74)+SUMPRODUCT((Fixture_Grupos!$E$3:$E$74=$C21)*Fixture_Grupos!$H$3:$H$74*Fixture_Grupos!$F$3:$F$74) -> 2 | J21: =H21-I21 -> 2 | K21: =3*E21+F21 -> 6 | L21: =SUMPRODUCT(--(($K$19:$K$22*1000+$J$19:$J$22*10+$H$19:$H$22)>($K21*1000+$J21*10+$H21)))+1 -> 2
